Workbook

Sheet MENU
A4: 1 | B4: Nombre del producto 1 | D4: 21 | E4: Nombre del producto 21 | G4: 41 | H4: Nombre del producto 41
A5: 2 | B5: Nombre del producto 2 | D5: 22 | E5: Nombre del producto 22 | G5: 42 | H5: Nombre del producto 42
A6: 3 | B6: Nombre del producto 3 | D6: 23 | E6: Nombre del producto 23 | G6: 43 | H6: Nombre del producto 43
A7: 4 | B7: Nombre del producto 4 | D7: 24 | E7: Nombre del producto 24 | G7: 44 | H7: Nombre del producto 44
A8: 5 | B8: Nombre del producto 5 | D8: 25 | E8: Nombre del producto 25 | G8: 45 | H8: Nombre del producto 45
A9: 6 | B9: Nombre del producto 6 | D9: 26 | E9: Nombre del producto 26 | G9: 46 | H9: Nombre del producto 46
A10: 7 | B10: Nombre del producto 7 | D10: 27 | E10: Nombre del producto 27 | G10: 47 | H10: Nombre del producto 47
A11: 8 | B11: Nombre del producto 8 | D11: 28 | E11: Nombre del producto 28 | G11: 48 | H11: Nombre del producto 48
A12: 9 | B12: Nombre del producto 9 | D12: 29 | E12: Nombre del producto 29 | G12: 49 | H12: Nombre del producto 49
A13: 10 | B13: Nombre del producto 10 | D13: 30 | E13: Nombre del producto 30 | G13: 50 | H13: Nombre del producto 50
A14: 11 | B14: Nombre del producto 11 | D14: 31 | E14: Nombre del producto 31 | G14: 51 | H14: Nombre del producto 51 | J14: CONVERTIDOR DE UNIDAD DE MEDIDA
A15: 12 | B15: Nombre del producto 12 | D15: 32 | E15: Nombre del producto 32 | G15: 52 | H15: Nombre del producto 52 | K15: g | L15: =CONVERT(J15,K15,M15) -> 0 | M15: kg
A16: 13 | B16: Nombre del producto 13 | D16: 33 | E16: Nombre del producto 33 | G16: 53 | H16: Nombre del producto 53 | K16: kg | L16: =CONVERT(J16,K16,M16) -> 0 | M16: g
A17: 14 | B17: Nombre del producto 14 | D17: 34 | E17: Nombre del producto 34 | G17: 54 | H17: Nombre del producto 54 | K17: l | L17: =CONVERT(J17,K17,M17) -> 0 | M17: cm3
A18: 15 | B18: Nombre del producto 15 | D18: 35 | E18: Nombre del producto35 | G18: 55 | H18: Nombre del producto 55 | K18: cm3 | L18: =CONVERT(J18,K18,M18) -> 0 | M18: l
A19: 16 | B19: Nombre del producto 16 | D19: 36 | E19: Nombre del producto 36 | G19: 56 | H19: Nombre del producto 56
A20: 17 | B20: Nombre del producto 17 | D20: 37 | E20: Nombre del producto 37 | G20: 57 | H20: Nombre del producto 57
A21: 18 | B21: Nombre del producto 18 | D21: 38 | E21: Nombre del producto 38 | G21: 58 | H21: Nombre del producto 58
A22: 19 | B22: Nombre del producto 19 | D22: 39 | E22: Nombre del producto 39 | G22: 59 | H22: Nombre del producto 59
A23: 20 | B23: Nombre del producto 20 | D23: 40 | E23: Nombre del producto 40 | G23: 60 | H23: Nombre del producto 60

Sheet Ingredientes
B2: INGREDIENTES PARA LAS RECETAS
C4: 25 | E4: 9000
C5: 1 | E5: =IFERROR(C5*E4/C4,0) -> 360
B7: INGREDIENTES | C7: PRECIO | D7: U. MEDIDA | E7: CATEGORÍA

Sheet Hoja1
K4: SILLA DE MADERA | O4: CUADRO DE RESUMEN MENSUAL
K5: Costo materiales: | L5: 3000
K6: Costo laboral: | L6: 600 | O6: INGRESOS TOTALES | P6: =SUM(P7:P8) -> 30100000 | Q6: =P6/P6 -> 1
K7: Costo fijo: | L7: 118 | O7: INGRESOS POR VENTAS | P7: 30000000 | Q7: =P7/$P$6 -> 0.99667774
K8: Costo Total | L8: =L5+L6+L7 -> 3718 | O8: OTROS INGRESOS | P8: 100000 | Q8: =P8/$P$6 -> 0.0033222591
K10: Precio de venta | L10: 6000 | O10: COSTOS TOTALES | P10: =SUM(P11:P14) -> 16750000 | Q10: =P10/$P$6 -> 0.55647841
K11: Utilidad en $ | L11: =L10-L8 -> 2282 | O11: MATERIALES | P11: 12500000 | Q11: =P11/$P$6 -> 0.41528239
K12: Utilidad en $ | L12: =L11/L10 -> 0.38033333 | O12: MANO DE OBRA | P12: 2200000 | Q12: =P12/$P$6 -> 0.073089701
K13: Punto de equilibrio (u) | L13: 393.33333 | O13: COSTOS FIJOS | P13: 1800000 | Q13: =P13/$P$6 -> 0.059800664
O14: OTROS EGRESOS | P14: 250000 | Q14: =P14/$P$6 -> 0.0083056478
O16: RESULTADO TOTAL | P16: =P6-P10 -> 13350000 | Q16: =P16/$P$6 -> 0.44352159

Sheet MO
C1: COSTOS LABORALES
B3: EMPLEADOS | C3: Sueldo mensual | D3: Horas trabajadas en el mes | E3: Costo por hora
E4: =IFERROR(C4/D4,0) -> 0
E5: =IFERROR(C5/D5,0) -> 0
E6: =IFERROR(C6/D6,0) -> 0
E7: =IFERROR(C7/D7,0) -> 0
E8: =IFERROR(C8/D8,0) -> 0
E9: =IFERROR(C9/D9,0) -> 0
E10: =IFERROR(C10/D10,0) -> 0
E11: =IFERROR(C11/D11,0) -> 0
E12: =IFERROR(C12/D12,0) -> 0
E13: =IFERROR(C13/D13,0) -> 0
E14: =IFERROR(C14/D14,0) -> 0
E15: =IFERROR(C15/D15,0) -> 0
... E17: =IFERROR(C17/D17,0) -> 0
C18: =SUM(C4:C17) -> 0 | D18: =SUM(D4:D17) -> 0 | E18: =SUM(E4:E17) -> 0

Sheet CIF
B2: COSTOS FIJOS | C2: UNIDADES TOTALES PRODUCIDAS POR MES | D2: =G64 -> 0
B3: CONCEPTO | C3: Monto mensual | D3: Costo fijo por unidad | F3: PRODUCTO | G3: Unidades producidas en el mes | H3: % de los Costos fijos absorbidos | I3: Costos fijos por unidad
D4: =IFERROR(C4/$D$2,"") | E4: 1 | F4: =MENU!B4 -> Nombre del producto 1 | H4: =IFERROR(G4/$D$2,"") | I4: =IFERROR(H4*$D$67,"")
D5: =IFERROR(C5/$D$2,"") | E5: 2 | F5: =MENU!B5 -> Nombre del producto 2 | H5: =IFERROR(G5/$D$2,"") | I5: =IFERROR(H5*$D$67,"")
D6: =IFERROR(C6/$D$2,"") | E6: 3 | F6: =MENU!B6 -> Nombre del producto 3 | H6: =IFERROR(G6/$D$2,"") | I6: =IFERROR(H6*$D$67,"")
D7: =IFERROR(C7/$D$2,"") | E7: 4 | F7: =MENU!B7 -> Nombre del producto 4 | H7: =IFERROR(G7/$D$2,"") | I7: =IFERROR(H7*$D$67,"")
D8: =IFERROR(C8/$D$2,"") | E8: 5 | F8: =MENU!B8 -> Nombre del producto 5 | H8: =IFERROR(G8/$D$2,"") | I8: =IFERROR(H8*$D$67,"")
D9: =IFERROR(C9/$D$2,"") | E9: 6 | F9: =MENU!B9 -> Nombre del producto 6 | H9: =IFERROR(G9/$D$2,"") | I9: =IFERROR(H9*$D$67,"")
D10: =IFERROR(C10/$D$2,"") | E10: 7 | F10: =MENU!B10 -> Nombre del producto 7 | H10: =IFERROR(G10/$D$2,"") | I10: =IFERROR(H10*$D$67,"")
D11: =IFERROR(C11/$D$2,"") | E11: 8 | F11: =MENU!B11 -> Nombre del producto 8 | H11: =IFERROR(G11/$D$2,"") | I11: =IFERROR(H11*$D$67,"")
D12: =IFERROR(C12/$D$2,"") | E12: 9 | F12: =MENU!B12 -> Nombre del producto 9 | H12: =IFERROR(G12/$D$2,"") | I12: =IFERROR(H12*$D$67,"")
D13: =IFERROR(C13/$D$2,"") | E13: 10 | F13: =MENU!B13 -> Nombre del producto 10 | H13: =IFERROR(G13/$D$2,"") | I13: =IFERROR(H13*$D$67,"")
D14: =IFERROR(C14/$D$2,"") | E14: 11 | F14: =MENU!B14 -> Nombre del producto 11 | H14: =IFERROR(G14/$D$2,"") | I14: =IFERROR(H14*$D$67,"")
D15: =IFERROR(C15/$D$2,"") | E15: 12 | F15: =MENU!B15 -> Nombre del producto 12 | H15: =IFERROR(G15/$D$2,"") | I15: =IFERROR(H15*$D$67,"")
... D23: =IFERROR(C23/$D$2,"") | E23: 20 | F23: =MENU!B23 -> Nombre del producto 20 | H23: =IFERROR(G23/$D$2,"") | I23: =IFERROR(H23*$D$67,"")
D24: =IFERROR(C24/$D$2,"") | E24: 21 | F24: =MENU!E4 -> Nombre del producto 21 | H24: =IFERROR(G24/$D$2,"") | I24: =IFERROR(H24*$D$67,"")
D25: =IFERROR(C25/$D$2,"") | E25: 22 | F25: =MENU!E5 -> Nombre del producto 22 | H25: =IFERROR(G25/$D$2,"") | I25: =IFERROR(H25*$D$67,"")
D26: =IFERROR(C26/$D$2,"") | E26: 23 | F26: =MENU!E6 -> Nombre del producto 23 | H26: =IFERROR(G26/$D$2,"") | I26: =IFERROR(H26*$D$67,"")
D27: =IFERROR(C27/$D$2,"") | E27: 24 | F27: =MENU!E7 -> Nombre del producto 24 | H27: =IFERROR(G27/$D$2,"") | I27: =IFERROR(H27*$D$67,"")
D28: =IFERROR(C28/$D$2,"") | E28: 25 | F28: =MENU!E8 -> Nombre del producto 25 | H28: =IFERROR(G28/$D$2,"") | I28: =IFERROR(H28*$D$67,"")
D29: =IFERROR(C29/$D$2,"") | E29: 26 | F29: =MENU!E9 -> Nombre del producto 26 | H29: =IFERROR(G29/$D$2,"") | I29: =IFERROR(H29*$D$67,"")
D30: =IFERROR(C30/$D$2,"") | E30: 27 | F30: =MENU!E10 -> Nombre del producto 27 | H30: =IFERROR(G30/$D$2,"") | I30: =IFERROR(H30*$D$67,"")
D31: =IFERROR(C31/$D$2,"") | E31: 28 | F31: =MENU!E11 -> Nombre del producto 28 | H31: =IFERROR(G31/$D$2,"") | I31: =IFERROR(H31*$D$67,"")
D32: =IFERROR(C32/$D$2,"") | E32: 29 | F32: =MENU!E12 -> Nombre del producto 29 | H32: =IFERROR(G32/$D$2,"") | I32: =IFERROR(H32*$D$67,"")
D33: =IFERROR(C33/$D$2,"") | E33: 30 | F33: =MENU!E13 -> Nombre del producto 30 | H33: =IFERROR(G33/$D$2,"") | I33: =IFERROR(H33*$D$67,"")
D34: =IFERROR(C34/$D$2,"") | E34: 31 | F34: =MENU!E14 -> Nombre del producto 31 | H34: =IFERROR(G34/$D$2,"") | I34: =IFERROR(H34*$D$67,"")
D35: =IFERROR(C35/$D$2,"") | E35: 32 | F35: =MENU!E15 -> Nombre del producto 32 | H35: =IFERROR(G35/$D$2,"") | I35: =IFERROR(H35*$D$67,"")
... D43: =IFERROR(C43/$D$2,"") | E43: 40 | F43: =MENU!E23 -> Nombre del producto 40 | H43: =IFERROR(G43/$D$2,"") | I43: =IFERROR(H43*$D$67,"")
D44: =IFERROR(C44/$D$2,"") | E44: 41 | F44: =MENU!H4 -> Nombre del producto 41 | H44: =IFERROR(G44/$D$2,"") | I44: =IFERROR(H44*$D$67,"")
D45: =IFERROR(C45/$D$2,"") | E45: 42 | F45: =MENU!H5 -> Nombre del producto 42 | H45: =IFERROR(G45/$D$2,"") | I45: =IFERROR(H45*$D$67,"")
D46: =IFERROR(C46/$D$2,"") | E46: 43 | F46: =MENU!H6 -> Nombre del producto 43 | H46: =IFERROR(G46/$D$2,"") | I46: =IFERROR(H46*$D$67,"")
D47: =IFERROR(C47/$D$2,"") | E47: 44 | F47: =MENU!H7 -> Nombre del producto 44 | H47: =IFERROR(G47/$D$2,"") | I47: =IFERROR(H47*$D$67,"")
D48: =IFERROR(C48/$D$2,"") | E48: 45 | F48: =MENU!H8 -> Nombre del producto 45 | H48: =IFERROR(G48/$D$2,"") | I48: =IFERROR(H48*$D$67,"")
D49: =IFERROR(C49/$D$2,"") | E49: 46 | F49: =MENU!H9 -> Nombre del producto 46 | H49: =IFERROR(G49/$D$2,"") | I49: =IFERROR(H49*$D$67,"")
D50: =IFERROR(C50/$D$2,"") | E50: 47 | F50: =MENU!H10 -> Nombre del producto 47 | H50: =IFERROR(G50/$D$2,"") | I50: =IFERROR(H50*$D$67,"")
D51: =IFERROR(C51/$D$2,"") | E51: 48 | F51: =MENU!H11 -> Nombre del producto 48 | H51: =IFERROR(G51/$D$2,"") | I51: =IFERROR(H51*$D$67,"")
D52: =IFERROR(C52/$D$2,"") | E52: 49 | F52: =MENU!H12 -> Nombre del producto 49 | H52: =IFERROR(G52/$D$2,"") | I52: =IFERROR(H52*$D$67,"")
D53: =IFERROR(C53/$D$2,"") | E53: 50 | F53: =MENU!H13 -> Nombre del producto 50 | H53: =IFERROR(G53/$D$2,"") | I53: =IFERROR(H53*$D$67,"")
D54: =IFERROR(C54/$D$2,"") | E54: 51 | F54: =MENU!H14 -> Nombre del producto 51 | H54: =IFERROR(G54/$D$2,"") | I54: =IFERROR(H54*$D$67,"")
D55: =IFERROR(C55/$D$2,"") | E55: 52 | F55: =MENU!H15 -> Nombre del producto 52 | H55: =IFERROR(G55/$D$2,"") | I55: =IFERROR(H55*$D$67,"")
...

Sheet Presupuesto
B2: # | C2: PRODUCTO | D2: PRECIO DE VENTA | E2: COSTO DE INGREDIENTES | F2: CANTIDAD VENDIDA | G2: VENTAS TOTALES | H2: TOTAL COSTO INGREDIENTES | I2: GANANCIA TOTAL | J2: % | T2: REGISTRO DE OTROS INGRESOS Y EGRESOS
B3: 1 | C3: =MENU!B4 -> Nombre del producto 1 | D3: {=INDIRECT(B3&"!I11")} -> 7000 | E3: {=INDIRECT(B3&"!I6")} -> 0 | G3: =D3*F3 -> 0 | H3: =E3*F3 -> 0 | I3: =G3-H3 -> 0 | J3: =IFERROR(I3/G3,"") | N3: CUADRO DE RESUMEN MENSUAL
B4: 2 | C4: =MENU!B5 -> Nombre del producto 2 | D4: {=INDIRECT(B4&"!I11")} -> 10000 | E4: {=INDIRECT(B4&"!I6")} -> 0 | G4: =D4*F4 -> 0 | H4: =E4*F4 -> 0 | I4: =G4-H4 -> 0 | J4: =IFERROR(I4/G4,"") | Z4: TOTAL | AA4: =SUM(AA6:AA25) -> 0
B5: 3 | C5: =MENU!B6 -> Nombre del producto 3 | D5: {=INDIRECT(B5&"!I11")} -> 5000 | E5: {=INDIRECT(B5&"!I6")} -> 0 | G5: =D5*F5 -> 0 | H5: =E5*F5 -> 0 | I5: =G5-H5 -> 0 | J5: =IFERROR(I5/G5,"") | N5: INGRESOS TOTALES | O5: =SUM(O6:O7) -> 0 | P5: =O5/O5 -> #DIV/0! | T5: FECHA | U5: MES | V5: DESCRIPCIÓN | AA5: MONTO
B6: 4 | C6: =MENU!B7 -> Nombre del producto 4 | D6: {=INDIRECT(B6&"!I11")} -> 5000 | E6: {=INDIRECT(B6&"!I6")} -> 0 | G6: =D6*F6 -> 0 | H6: =E6*F6 -> 0 | I6: =G6-H6 -> 0 | J6: =IFERROR(I6/G6,"") | N6: INGRESOS POR VENTAS | O6: =G63 -> 0 | P6: =O6/$O$5 -> #DIV/0! | U6: =TEXT(T6,"MMMM") -> enero
B7: 5 | C7: =MENU!B8 -> Nombre del producto 5 | D7: {=INDIRECT(B7&"!I11")} -> 5000 | E7: {=INDIRECT(B7&"!I6")} -> 0 | G7: =D7*F7 -> 0 | H7: =E7*F7 -> 0 | I7: =G7-H7 -> 0 | J7: =IFERROR(I7/G7,"") | N7: OTROS INGRESOS | O7: =AA4 -> 0 | P7: =O7/$O$5 -> #DIV/0! | U7: =TEXT(T7,"MMMM") -> enero
B8: 6 | C8: =MENU!B9 -> Nombre del producto 6 | D8: {=INDIRECT(B8&"!I11")} -> 5000 | E8: {=INDIRECT(B8&"!I6")} -> 0 | G8: =D8*F8 -> 0 | H8: =E8*F8 -> 0 | I8: =G8-H8 -> 0 | J8: =IFERROR(I8/G8,"") | U8: =TEXT(T8,"MMMM") -> enero
B9: 7 | C9: =MENU!B10 -> Nombre del producto 7 | D9: {=INDIRECT(B9&"!I11")} -> 5000 | E9: {=INDIRECT(B9&"!I6")} -> 0 | G9: =D9*F9 -> 0 | H9: =E9*F9 -> 0 | I9: =G9-H9 -> 0 | J9: =IFERROR(I9/G9,"") | N9: COSTOS TOTALES | O9: =SUM(O10:O13) -> 0 | P9: =O9/$O$5 -> #DIV/0! | U9: =TEXT(T9,"MMMM") -> enero
B10: 8 | C10: =MENU!B11 -> Nombre del producto 8 | D10: {=INDIRECT(B10&"!I11")} -> 5000 | E10: {=INDIRECT(B10&"!I6")} -> 0 | G10: =D10*F10 -> 0 | H10: =E10*F10 -> 0 | I10: =G10-H10 -> 0 | J10: =IFERROR(I10/G10,"") | N10: INGREDIENTES | O10: =H63 -> 0 | P10: =O10/$O$5 -> #DIV/0! | U10: =TEXT(T10,"MMMM") -> enero
B11: 9 | C11: =MENU!B12 -> Nombre del producto 9 | D11: {=INDIRECT(B11&"!I11")} -> 5000 | E11: {=INDIRECT(B11&"!I6")} -> 0 | G11: =D11*F11 -> 0 | H11: =E11*F11 -> 0 | I11: =G11-H11 -> 0 | J11: =IFERROR(I11/G11,"") | N11: MANO DE OBRA | O11: =MO!C18 -> 0 | P11: =O11/$O$5 -> #DIV/0! | U11: =TEXT(T11,"MMMM") -> enero
B12: 10 | C12: =MENU!B13 -> Nombre del producto 10 | D12: {=INDIRECT(B12&"!I11")} -> 5000 | E12: {=INDIRECT(B12&"!I6")} -> 0 | G12: =D12*F12 -> 0 | H12: =E12*F12 -> 0 | I12: =G12-H12 -> 0 | J12: =IFERROR(I12/G12,"") | N12: COSTOS FIJOS | O12: =CIF!C67 -> 0 | P12: =O12/$O$5 -> #DIV/0! | U12: =TEXT(T12,"MMMM") -> enero
B13: 11 | C13: =MENU!B14 -> Nombre del producto 11 | D13: {=INDIRECT(B13&"!I11")} -> 5000 | E13: {=INDIRECT(B13&"!I6")} -> 0 | G13: =D13*F13 -> 0 | H13: =E13*F13 -> 0 | I13: =G13-H13 -> 0 | J13: =IFERROR(I13/G13,"") | N13: OTROS EGRESOS | O13: =AA27 -> 0 | P13: =O13/$O$5 -> #DIV/0! | U13: =TEXT(T13,"MMMM") -> enero
B14: 12 | C14: =MENU!B15 -> Nombre del producto 12 | D14: {=INDIRECT(B14&"!I11")} -> 5000 | E14: {=INDIRECT(B14&"!I6")} -> 0 | G14: =D14*F14 -> 0 | H14: =E14*F14 -> 0 | I14: =G14-H14 -> 0 | J14: =IFERROR(I14/G14,"") | U14: =TEXT(T14,"MMMM") -> enero
B15: 13 | C15: =MENU!B16 -> Nombre del producto 13 | D15: {=INDIRECT(B15&"!I11")} -> 5000 | E15: {=INDIRECT(B15&"!I6")} -> 0 | G15: =D15*F15 -> 0 | H15: =E15*F15 -> 0 | I15: =G15-H15 -> 0 | J15: =IFERROR(I15/G15,"") | N15: RESULTADO TOTAL | O15: =O5-O9 -> 0 | P15: =O15/$O$5 -> #DIV/0! | U15: =TEXT(T15,"MMMM") -> enero
B16: 14 | C16: =MENU!B17 -> Nombre del producto 14 | D16: {=INDIRECT(B16&"!I11")} -> 5000 | E16: {=INDIRECT(B16&"!I6")} -> 0 | G16: =D16*F16 -> 0 | H16: =E16*F16 -> 0 | I16: =G16-H16 -> 0 | J16: =IFERROR(I16/G16,"") | U16: =TEXT(T16,"MMMM") -> enero
B17: 15 | C17: =MENU!B18 -> Nombre del producto 15 | D17: {=INDIRECT(B17&"!I11")} -> 5000 | E17: {=INDIRECT(B17&"!I6")} -> 0 | G17: =D17*F17 -> 0 | H17: =E17*F17 -> 0 | I17: =G17-H17 -> 0 | J17: =IFERROR(I17/G17,"") | U17: =TEXT(T17,"MMMM") -> enero
B18: 16 | C18: =MENU!B19 -> Nombre del producto 16 | D18: {=INDIRECT(B18&"!I11")} -> 5000 | E18: {=INDIRECT(B18&"!I6")} -> 0 | G18: =D18*F18 -> 0 | H18: =E18*F18 -> 0 | J18: =IFERROR(I18/G18,"") | U18: =TEXT(T18,"MMMM") -> enero
B19: 17 | C19: =MENU!B20 -> Nombre del producto 17 | D19: {=INDIRECT(B19&"!I11")} -> 5000 | E19: {=INDIRECT(B19&"!I6")} -> 0 | G19: =D19*F19 -> 0 | H19: =E19*F19 -> 0 | I19: =G19-H19 -> 0 | J19: =IFERROR(I19/G19,"") | U19: =TEXT(T19,"MMMM") -> enero
B20: 18 | C20: =MENU!B21 -> Nombre del producto 18 | D20: {=INDIRECT(B20&"!I11")} -> 5000 | E20: {=INDIRECT(B20&"!I6")} -> 0 | G20: =D20*F20 -> 0 | H20: =E20*F20 -> 0 | I20: =G20-H20 -> 0 | J20: =IFERROR(I20/G20,"") | U20: =TEXT(T20,"MMMM") -> enero
B21: 19 | C21: =MENU!B22 -> Nombre del producto 19 | D21: {=INDIRECT(B21&"!I11")} -> 5000 | E21: {=INDIRECT(B21&"!I6")} -> 0 | G21: =D21*F21 -> 0 | H21: =E21*F21 -> 0 | I21: =G21-H21 -> 0 | J21: =IFERROR(I21/G21,"") | U21: =TEXT(T21,"MMMM") -> enero
B22: 20 | C22: =MENU!B23 -> Nombre del producto 20 | D22: {=INDIRECT(B22&"!I11")} -> 5000 | E22: {=INDIRECT(B22&"!I6")} -> 0 | G22: =D22*F22 -> 0 | H22: =E22*F22 -> 0 | I22: =G22-H22 -> 0 | J22: =IFERROR(I22/G22,"") | U22: =TEXT(T22,"MMMM") -> enero
B23: 21 | C23: =MENU!E4 -> Nombre del producto 21 | D23: {=INDIRECT(B23&"!I11")} -> 5000 | E23: {=INDIRECT(B23&"!I6")} -> 0 | G23: =D23*F23 -> 0 | H23: =E23*F23 -> 0 | I23: =G23-H23 -> 0 | J23: =IFERROR(I23/G23,"") | U23: =TEXT(T23,"MMMM") -> enero
B24: 22 | C24: =MENU!E5 -> Nombre del producto 22 | D24: {=INDIRECT(B24&"!I11")} -> 5000 | E24: {=INDIRECT(B24&"!I6")} -> 0 | G24: =D24*F24 -> 0 | H24: =E24*F24 -> 0 | I24: =G24-H24 -> 0 | J24: =IFERROR(I24/G24,"") | U24: =TEXT(T24,"MMMM") -> enero
B25: 23 | C25: =MENU!E6 -> Nombre del producto 23 | D25: {=INDIRECT(B25&"!I11")} -> 5000 | E25: {=INDIRECT(B25&"!I6")} -> 0 | G25: =D25*F25 -> 0 | H25: =E25*F25 -> 0 | I25: =G25-H25 -> 0 | J25: =IFERROR(I25/G25,"") | U25: =TEXT(T25,"MMMM") -> enero
B26: 24 | C26: =MENU!E7 -> Nombre del producto 24 | D26: {=INDIRECT(B26&"!I11")} -> 5000 | E26: {=INDIRECT(B26&"!I6")} -> 0 | G26: =D26*F26 -> 0 | H26: =E26*F26 -> 0 | I26: =G26-H26 -> 0 | J26: =IFERROR(I26/G26,"")
B27: 25 | C27: =MENU!E8 -> Nombre del producto 25 | D27: {=INDIRECT(B27&"!I11")} -> 5000 | E27: {=INDIRECT(B27&"!I6")} -> 0 | G27: =D27*F27 -> 0 | H27: =E27*F27 -> 0 | I27: =G27-H27 -> 0 | J27: =IFERROR(I27/G27,"") | Z27: TOTAL | AA27: =SUM(AA29:AA63) -> 0
B28: 26 | C28: =MENU!E9 -> Nombre del producto 26 | D28: {=INDIRECT(B28&"!I11")} -> 5000 | E28: {=INDIRECT(B28&"!I6")} -> 0 | G28: =D28*F28 -> 0 | H28: =E28*F28 -> 0 | I28: =G28-H28 -> 0 | J28: =IFERROR(I28/G28,"") | N28: PRODUCTOS | O28: GANANCIA | T28: FECHA | U28: MES | V28: DESCRIPCIÓN | AA28: MONTO
B29: 27 | C29: =MENU!E10 -> Nombre del producto 27 | D29: {=INDIRECT(B29&"!I11")} -> 5000 | E29: {=INDIRECT(B29&"!I6")} -> 0 | G29: =D29*F29 -> 0 | H29: =E29*F29 -> 0 | I29: =G29-H29 -> 0 | J29: =IFERROR(I29/G29,"") | N29: Nombre del producto 1 | O29: 30000000 | U29: =TEXT(T29,"MMMM") -> enero
B30: 28 | C30: =MENU!E11 -> Nombre del producto 28 | D30: {=INDIRECT(B30&"!I11")} -> 5000 | E30: {=INDIRECT(B30&"!I6")} -> 0 | G30: =D30*F30 -> 0 | H30: =E30*F30 -> 0 | I30: =G30-H30 -> 0 | J30: =IFERROR(I30/G30,"") | N30: Nombre del producto 5 | O30: 30000 | U30: =TEXT(T30,"MMMM") -> enero
B31: 29 | C31: =MENU!E12 -> Nombre del producto 29 | D31: {=INDIRECT(B31&"!I11")} -> 5000 | E31: {=INDIRECT(B31&"!I6")} -> 0 | G31: =D31*F31 -> 0 | H31: =E31*F31 -> 0 | I31: =G31-H31 -> 0 | J31: =IFERROR(I31/G31,"") | N31: Nombre del producto 4 | O31: 20000 | U31: =TEXT(T31,"MMMM") -> enero
B32: 30 | C32: =MENU!E13 -> Nombre del producto 30 | D32: {=INDIRECT(B32&"!I11")} -> 5000 | E32: {=INDIRECT(B32&"!I6")} -> 0 | G32: =D32*F32 -> 0 | H32: =E32*F32 -> 0 | I32: =G32-H32 -> 0 | J32: =IFERROR(I32/G32,"") | N32: Nombre del producto 3 | O32: 10000 | U32: =TEXT(T32,"MMMM") -> enero
B33: 31 | C33: =MENU!E14 -> Nombre del producto 31 | D33: {=INDIRECT(B33&"!I11")} -> 5000 | E33: {=INDIRECT(B33&"!I6")} -> 0 | G33: =D33*F33 -> 0 | H33: =E33*F33 -> 0 | I33: =G33-H33 -> 0 | J33: =IFERROR(I33/G33,"") | N33: Nombre del producto 2 | O33: 5000 | U33: =TEXT(T33,"MMMM") -> enero
B34: 32 | C34: =MENU!E15 -> Nombre del producto 32 | D34: {=INDIRECT(B34&"!I11")} -> 5000 | E34: {=INDIRECT(B34&"!I6")} -> 0 | G34: =D34*F34 -> 0 | H34: =E34*F34 -> 0 | I34: =G34-H34 -> 0 | J34: =IFERROR(I34/G34,"") | N34: Total general | O34: 30065000 | U34: =TEXT(T34,"MMMM") -> enero
B35: 33 | C35: =MENU!E16 -> Nombre del producto 33 | D35: {=INDIRECT(B35&"!I11")} -> 5000 | E35: {=INDIRECT(B35&"!I6")} -> 0 | G35: =D35*F35 -> 0 | H35: =E35*F35 -> 0 | I35: =G35-H35 -> 0 | J35: =IFERROR(I35/G35,"") | U35: =TEXT(T35,"MMMM") -> enero
B36: 34 | C36: =MENU!E17 -> Nombre del producto 34 | D36: {=INDIRECT(B36&"!I11")} -> 5000 | E36: {=INDIRECT(B36&"!I6")} -> 0 | G36: =D36*F36 -> 0 | H36: =E36*F36 -> 0 | I36: =G36-H36 -> 0 | J36: =IFERROR(I36/G36,"") | U36: =TEXT(T36,"MMMM") -> enero
B37: 35 | C37: =MENU!E18 -> Nombre del producto35 | D37: {=INDIRECT(B37&"!I11")} -> 5000 | E37: {=INDIRECT(B37&"!I6")} -> 0 | G37: =D37*F37 -> 0 | H37: =E37*F37 -> 0 | I37: =G37-H37 -> 0 | J37: =IFERROR(I37/G37,"") | U37: =TEXT(T37,"MMMM") -> enero
B38: 36 | C38: =MENU!E19 -> Nombre del producto 36 | D38: {=INDIRECT(B38&"!I11")} -> 5000 | E38: {=INDIRECT(B38&"!I6")} -> 0 | G38: =D38*F38 -> 0 | H38: =E38*F38 -> 0 | I38: =G38-H38 -> 0 | J38: =IFERROR(I38/G38,"") | U38: =TEXT(T38,"MMMM") -> enero
B39: 37 | C39: =MENU!E20 -> Nombre del producto 37 | D39: {=INDIRECT(B39&"!I11")} -> 5000 | E39: {=INDIRECT(B39&"!I6")} -> 0 | G39: =D39*F39 -> 0 | H39: =E39*F39 -> 0 | I39: =G39-H39 -> 0 | J39: =IFERROR(I39/G39,"") | U39: =TEXT(T39,"MMMM") -> enero
B40: 38 | C40: =MENU!E21 -> Nombre del producto 38 | D40: {=INDIRECT(B40&"!I11")} -> 5000 | E40: {=INDIRECT(B40&"!I6")} -> 0 | G40: =D40*F40 -> 0 | H40: =E40*F40 -> 0 | I40: =G40-H40 -> 0 | J40: =IFERROR(I40/G40,"") | U40: =TEXT(T40,"MMMM") -> enero
B41: 39 | C41: =MENU!E22 -> Nombre del producto 39 | D41: {=INDIRECT(B41&"!I11")} -> 5000 | E41: {=INDIRECT(B41&"!I6")} -> 0 | G41: =D41*F41 -> 0 | H41: =E41*F41 -> 0 | I41: =G41-H41 -> 0 | J41: =IFERROR(I41/G41,"") | U41: =TEXT(T41,"MMMM") -> enero
...

Sheet Delivery
C2: APLICACIONES DE DELIVERY
C4: En caso de que el porcentaje sea distinto o no corresponda, modificar el porcentaje/número en la celda en amarillo
F5: 0.25 | G5: 0.21 | H5: 0.025 | I5: 800
B6: # | C6: PRODUCTO | D6: PRECIO DE VENTA | F6: COMISIÓN APP | G6: IVA 21% | H6: PAGO ONLINE | I6: ENVIO PLUS PROMEDIO | J6: TOTAL COSTOS | L6: INGRESO NETO | M6: % | O6: PRECIO VENTA APPS
B7: 1 | C7: =MENU!B4 -> Nombre del producto 1 | D7: =Presupuesto!D3 -> 7000 | F7: =D7*$F$5 -> 1750 | G7: =F7*$G$5 -> 367.5 | H7: =D7*$H$5 -> 175 | I7: =$I$5 -> 800 | J7: =F7+G7+H7+I7 -> 3092.5 | L7: =D7-J7 -> 3907.5 | M7: =L7/D7 -> 0.55821429 | O7: =(D7+$I$5)/(1-(F7+G7+H7)/D7) -> 11598.513
B8: 2 | C8: =MENU!B5 -> Nombre del producto 2 | D8: =Presupuesto!D4 -> 10000 | F8: =D8*$F$5 -> 2500 | G8: =F8*$G$5 -> 525 | H8: =D8*$H$5 -> 250 | I8: =$I$5 -> 800 | J8: =F8+G8+H8+I8 -> 4075 | L8: =D8-J8 -> 5925 | M8: =L8/D8 -> 0.5925 | O8: =(D8+$I$5)/(1-(F8+G8+H8)/D8) -> 16059.48
B9: 3 | C9: =MENU!B6 -> Nombre del producto 3 | D9: =Presupuesto!D5 -> 5000 | F9: =D9*$F$5 -> 1250 | G9: =F9*$G$5 -> 262.5 | H9: =D9*$H$5 -> 125 | I9: =$I$5 -> 800 | J9: =F9+G9+H9+I9 -> 2437.5 | L9: =D9-J9 -> 2562.5 | M9: =L9/D9 -> 0.5125 | O9: =(D9+$I$5)/(1-(F9+G9+H9)/D9) -> 8624.5353
B10: 4 | C10: =MENU!B7 -> Nombre del producto 4 | D10: =Presupuesto!D6 -> 5000 | F10: =D10*$F$5 -> 1250 | G10: =F10*$G$5 -> 262.5 | H10: =D10*$H$5 -> 125 | I10: =$I$5 -> 800 | J10: =F10+G10+H10+I10 -> 2437.5 | L10: =D10-J10 -> 2562.5 | M10: =L10/D10 -> 0.5125 | O10: =(D10+$I$5)/(1-(F10+G10+H10)/D10) -> 8624.5353
B11: 5 | C11: =MENU!B8 -> Nombre del producto 5 | D11: =Presupuesto!D7 -> 5000 | F11: =D11*$F$5 -> 1250 | G11: =F11*$G$5 -> 262.5 | H11: =D11*$H$5 -> 125 | I11: =$I$5 -> 800 | J11: =F11+G11+H11+I11 -> 2437.5 | L11: =D11-J11 -> 2562.5 | M11: =L11/D11 -> 0.5125 | O11: =(D11+$I$5)/(1-(F11+G11+H11)/D11) -> 8624.5353
B12: 6 | C12: =MENU!B9 -> Nombre del producto 6 | D12: =Presupuesto!D8 -> 5000 | F12: =D12*$F$5 -> 1250 | G12: =F12*$G$5 -> 262.5 | H12: =D12*$H$5 -> 125 | I12: =$I$5 -> 800 | J12: =F12+G12+H12+I12 -> 2437.5 | L12: =D12-J12 -> 2562.5 | M12: =L12/D12 -> 0.5125 | O12: =(D12+$I$5)/(1-(F12+G12+H12)/D12) -> 8624.5353
B13: 7 | C13: =MENU!B10 -> Nombre del producto 7 | D13: =Presupuesto!D9 -> 5000 | F13: =D13*$F$5 -> 1250 | G13: =F13*$G$5 -> 262.5 | H13: =D13*$H$5 -> 125 | I13: =$I$5 -> 800 | J13: =F13+G13+H13+I13 -> 2437.5 | L13: =D13-J13 -> 2562.5 | M13: =L13/D13 -> 0.5125 | O13: =(D13+$I$5)/(1-(F13+G13+H13)/D13) -> 8624.5353
B14: 8 | C14: =MENU!B11 -> Nombre del producto 8 | D14: =Presupuesto!D10 -> 5000 | F14: =D14*$F$5 -> 1250 | G14: =F14*$G$5 -> 262.5 | H14: =D14*$H$5 -> 125 | I14: =$I$5 -> 800 | J14: =F14+G14+H14+I14 -> 2437.5 | L14: =D14-J14 -> 2562.5 | M14: =L14/D14 -> 0.5125 | O14: =(D14+$I$5)/(1-(F14+G14+H14)/D14) -> 8624.5353
B15: 9 | C15: =MENU!B12 -> Nombre del producto 9 | D15: =Presupuesto!D11 -> 5000 | F15: =D15*$F$5 -> 1250 | G15: =F15*$G$5 -> 262.5 | H15: =D15*$H$5 -> 125 | I15: =$I$5 -> 800 | J15: =F15+G15+H15+I15 -> 2437.5 | L15: =D15-J15 -> 2562.5 | M15: =L15/D15 -> 0.5125 | O15: =(D15+$I$5)/(1-(F15+G15+H15)/D15) -> 8624.5353
B16: 10 | C16: =MENU!B13 -> Nombre del producto 10 | D16: =Presupuesto!D12 -> 5000 | F16: =D16*$F$5 -> 1250 | G16: =F16*$G$5 -> 262.5 | H16: =D16*$H$5 -> 125 | I16: =$I$5 -> 800 | J16: =F16+G16+H16+I16 -> 2437.5 | L16: =D16-J16 -> 2562.5 | M16: =L16/D16 -> 0.5125 | O16: =(D16+$I$5)/(1-(F16+G16+H16)/D16) -> 8624.5353
B17: 11 | C17: =MENU!B14 -> Nombre del producto 11 | D17: =Presupuesto!D13 -> 5000 | F17: =D17*$F$5 -> 1250 | G17: =F17*$G$5 -> 262.5 | H17: =D17*$H$5 -> 125 | I17: =$I$5 -> 800 | J17: =F17+G17+H17+I17 -> 2437.5 | L17: =D17-J17 -> 2562.5 | M17: =L17/D17 -> 0.5125 | O17: =(D17+$I$5)/(1-(F17+G17+H17)/D17) -> 8624.5353
B18: 12 | C18: =MENU!B15 -> Nombre del producto 12 | D18: =Presupuesto!D14 -> 5000 | F18: =D18*$F$5 -> 1250 | G18: =F18*$G$5 -> 262.5 | H18: =D18*$H$5 -> 125 | I18: =$I$5 -> 800 | J18: =F18+G18+H18+I18 -> 2437.5 | L18: =D18-J18 -> 2562.5 | M18: =L18/D18 -> 0.5125 | O18: =(D18+$I$5)/(1-(F18+G18+H18)/D18) -> 8624.5353
... B26: 20 | C26: =MENU!B23 -> Nombre del producto 20 | D26: =Presupuesto!D22 -> 5000 | F26: =D26*$F$5 -> 1250 | G26: =F26*$G$5 -> 262.5 | H26: =D26*$H$5 -> 125 | I26: =$I$5 -> 800 | J26: =F26+G26+H26+I26 -> 2437.5 | L26: =D26-J26 -> 2562.5 | M26: =L26/D26 -> 0.5125 | O26: =(D26+$I$5)/(1-(F26+G26+H26)/D26) -> 8624.5353
B27: 21 | C27: =MENU!E4 -> Nombre del producto 21 | D27: =Presupuesto!D23 -> 5000 | F27: =D27*$F$5 -> 1250 | G27: =F27*$G$5 -> 262.5 | H27: =D27*$H$5 -> 125 | I27: =$I$5 -> 800 | J27: =F27+G27+H27+I27 -> 2437.5 | L27: =D27-J27 -> 2562.5 | M27: =L27/D27 -> 0.5125 | O27: =(D27+$I$5)/(1-(F27+G27+H27)/D27) -> 8624.5353
B28: 22 | C28: =MENU!E5 -> Nombre del producto 22 | D28: =Presupuesto!D24 -> 5000 | F28: =D28*$F$5 -> 1250 | G28: =F28*$G$5 -> 262.5 | H28: =D28*$H$5 -> 125 | I28: =$I$5 -> 800 | J28: =F28+G28+H28+I28 -> 2437.5 | L28: =D28-J28 -> 2562.5 | M28: =L28/D28 -> 0.5125 | O28: =(D28+$I$5)/(1-(F28+G28+H28)/D28) -> 8624.5353
B29: 23 | C29: =MENU!E6 -> Nombre del producto 23 | D29: =Presupuesto!D25 -> 5000 | F29: =D29*$F$5 -> 1250 | G29: =F29*$G$5 -> 262.5 | H29: =D29*$H$5 -> 125 | I29: =$I$5 -> 800 | J29: =F29+G29+H29+I29 -> 2437.5 | L29: =D29-J29 -> 2562.5 | M29: =L29/D29 -> 0.5125 | O29: =(D29+$I$5)/(1-(F29+G29+H29)/D29) -> 8624.5353
B30: 24 | C30: =MENU!E7 -> Nombre del producto 24 | D30: =Presupuesto!D26 -> 5000 | F30: =D30*$F$5 -> 1250 | G30: =F30*$G$5 -> 262.5 | H30: =D30*$H$5 -> 125 | I30: =$I$5 -> 800 | J30: =F30+G30+H30+I30 -> 2437.5 | L30: =D30-J30 -> 2562.5 | M30: =L30/D30 -> 0.5125 | O30: =(D30+$I$5)/(1-(F30+G30+H30)/D30) -> 8624.5353
B31: 25 | C31: =MENU!E8 -> Nombre del producto 25 | D31: =Presupuesto!D27 -> 5000 | F31: =D31*$F$5 -> 1250 | G31: =F31*$G$5 -> 262.5 | H31: =D31*$H$5 -> 125 | I31: =$I$5 -> 800 | J31: =F31+G31+H31+I31 -> 2437.5 | L31: =D31-J31 -> 2562.5 | M31: =L31/D31 -> 0.5125 | O31: =(D31+$I$5)/(1-(F31+G31+H31)/D31) -> 8624.5353
B32: 26 | C32: =MENU!E9 -> Nombre del producto 26 | D32: =Presupuesto!D28 -> 5000 | F32: =D32*$F$5 -> 1250 | G32: =F32*$G$5 -> 262.5 | H32: =D32*$H$5 -> 125 | I32: =$I$5 -> 800 | J32: =F32+G32+H32+I32 -> 2437.5 | L32: =D32-J32 -> 2562.5 | M32: =L32/D32 -> 0.5125 | O32: =(D32+$I$5)/(1-(F32+G32+H32)/D32) -> 8624.5353
B33: 27 | C33: =MENU!E10 -> Nombre del producto 27 | D33: =Presupuesto!D29 -> 5000 | F33: =D33*$F$5 -> 1250 | G33: =F33*$G$5 -> 262.5 | H33: =D33*$H$5 -> 125 | I33: =$I$5 -> 800 | J33: =F33+G33+H33+I33 -> 2437.5 | L33: =D33-J33 -> 2562.5 | M33: =L33/D33 -> 0.5125 | O33: =(D33+$I$5)/(1-(F33+G33+H33)/D33) -> 8624.5353
B34: 28 | C34: =MENU!E11 -> Nombre del producto 28 | D34: =Presupuesto!D30 -> 5000 | F34: =D34*$F$5 -> 1250 | G34: =F34*$G$5 -> 262.5 | H34: =D34*$H$5 -> 125 | I34: =$I$5 -> 800 | J34: =F34+G34+H34+I34 -> 2437.5 | L34: =D34-J34 -> 2562.5 | M34: =L34/D34 -> 0.5125 | O34: =(D34+$I$5)/(1-(F34+G34+H34)/D34) -> 8624.5353
B35: 29 | C35: =MENU!E12 -> Nombre del producto 29 | D35: =Presupuesto!D31 -> 5000 | F35: =D35*$F$5 -> 1250 | G35: =F35*$G$5 -> 262.5 | H35: =D35*$H$5 -> 125 | I35: =$I$5 -> 800 | J35: =F35+G35+H35+I35 -> 2437.5 | L35: =D35-J35 -> 2562.5 | M35: =L35/D35 -> 0.5125 | O35: =(D35+$I$5)/(1-(F35+G35+H35)/D35) -> 8624.5353
B36: 30 | C36: =MENU!E13 -> Nombre del producto 30 | D36: =Presupuesto!D32 -> 5000 | F36: =D36*$F$5 -> 1250 | G36: =F36*$G$5 -> 262.5 | H36: =D36*$H$5 -> 125 | I36: =$I$5 -> 800 | J36: =F36+G36+H36+I36 -> 2437.5 | L36: =D36-J36 -> 2562.5 | M36: =L36/D36 -> 0.5125 | O36: =(D36+$I$5)/(1-(F36+G36+H36)/D36) -> 8624.5353
B37: 31 | C37: =MENU!E14 -> Nombre del producto 31 | D37: =Presupuesto!D33 -> 5000 | F37: =D37*$F$5 -> 1250 | G37: =F37*$G$5 -> 262.5 | H37: =D37*$H$5 -> 125 | I37: =$I$5 -> 800 | J37: =F37+G37+H37+I37 -> 2437.5 | L37: =D37-J37 -> 2562.5 | M37: =L37/D37 -> 0.5125 | O37: =(D37+$I$5)/(1-(F37+G37+H37)/D37) -> 8624.5353
B38: 32 | C38: =MENU!E15 -> Nombre del producto 32 | D38: =Presupuesto!D34 -> 5000 | F38: =D38*$F$5 -> 1250 | G38: =F38*$G$5 -> 262.5 | H38: =D38*$H$5 -> 125 | I38: =$I$5 -> 800 | J38: =F38+G38+H38+I38 -> 2437.5 | L38: =D38-J38 -> 2562.5 | M38: =L38/D38 -> 0.5125 | O38: =(D38+$I$5)/(1-(F38+G38+H38)/D38) -> 8624.5353
... B46: 40 | C46: =MENU!E23 -> Nombre del producto 40 | D46: =Presupuesto!D42 -> 5000 | F46: =D46*$F$5 -> 1250 | G46: =F46*$G$5 -> 262.5 | H46: =D46*$H$5 -> 125 | I46: =$I$5 -> 800 | J46: =F46+G46+H46+I46 -> 2437.5 | L46: =D46-J46 -> 2562.5 | M46: =L46/D46 -> 0.5125 | O46: =(D46+$I$5)/(1-(F46+G46+H46)/D46) -> 8624.5353
B47: 41 | C47: =MENU!H4 -> Nombre del producto 41 | D47: =Presupuesto!D43 -> 5000 | F47: =D47*$F$5 -> 1250 | G47: =F47*$G$5 -> 262.5 | H47: =D47*$H$5 -> 125 | I47: =$I$5 -> 800 | J47: =F47+G47+H47+I47 -> 2437.5 | L47: =D47-J47 -> 2562.5 | M47: =L47/D47 -> 0.5125 | O47: =(D47+$I$5)/(1-(F47+G47+H47)/D47) -> 8624.5353
B48: 42 | C48: =MENU!H5 -> Nombre del producto 42 | D48: =Presupuesto!D44 -> 5000 | F48: =D48*$F$5 -> 1250 | G48: =F48*$G$5 -> 262.5 | H48: =D48*$H$5 -> 125 | I48: =$I$5 -> 800 | J48: =F48+G48+H48+I48 -> 2437.5 | L48: =D48-J48 -> 2562.5 | M48: =L48/D48 -> 0.5125 | O48: =(D48+$I$5)/(1-(F48+G48+H48)/D48) -> 8624.5353
B49: 43 | C49: =MENU!H6 -> Nombre del producto 43 | D49: =Presupuesto!D45 -> 5000 | F49: =D49*$F$5 -> 1250 | G49: =F49*$G$5 -> 262.5 | H49: =D49*$H$5 -> 125 | I49: =$I$5 -> 800 | J49: =F49+G49+H49+I49 -> 2437.5 | L49: =D49-J49 -> 2562.5 | M49: =L49/D49 -> 0.5125 | O49: =(D49+$I$5)/(1-(F49+G49+H49)/D49) -> 8624.5353
B50: 44 | C50: =MENU!H7 -> Nombre del producto 44 | D50: =Presupuesto!D46 -> 5000 | F50: =D50*$F$5 -> 1250 | G50: =F50*$G$5 -> 262.5 | H50: =D50*$H$5 -> 125 | I50: =$I$5 -> 800 | J50: =F50+G50+H50+I50 -> 2437.5 | L50: =D50-J50 -> 2562.5 | M50: =L50/D50 -> 0.5125 | O50: =(D50+$I$5)/(1-(F50+G50+H50)/D50) -> 8624.5353
B51: 45 | C51: =MENU!H8 -> Nombre del producto 45 | D51: =Presupuesto!D47 -> 5000 | F51: =D51*$F$5 -> 1250 | G51: =F51*$G$5 -> 262.5 | H51: =D51*$H$5 -> 125 | I51: =$I$5 -> 800 | J51: =F51+G51+H51+I51 -> 2437.5 | L51: =D51-J51 -> 2562.5 | M51: =L51/D51 -> 0.5125 | O51: =(D51+$I$5)/(1-(F51+G51+H51)/D51) -> 8624.5353
B52: 46 | C52: =MENU!H9 -> Nombre del producto 46 | D52: =Presupuesto!D48 -> 5000 | F52: =D52*$F$5 -> 1250 | G52: =F52*$G$5 -> 262.5 | H52: =D52*$H$5 -> 125 | I52: =$I$5 -> 800 | J52: =F52+G52+H52+I52 -> 2437.5 | L52: =D52-J52 -> 2562.5 | M52: =L52/D52 -> 0.5125 | O52: =(D52+$I$5)/(1-(F52+G52+H52)/D52) -> 8624.5353
B53: 47 | C53: =MENU!H10 -> Nombre del producto 47 | D53: =Presupuesto!D49 -> 5000 | F53: =D53*$F$5 -> 1250 | G53: =F53*$G$5 -> 262.5 | H53: =D53*$H$5 -> 125 | I53: =$I$5 -> 800 | J53: =F53+G53+H53+I53 -> 2437.5 | L53: =D53-J53 -> 2562.5 | M53: =L53/D53 -> 0.5125 | O53: =(D53+$I$5)/(1-(F53+G53+H53)/D53) -> 8624.5353
B54: 48 | C54: =MENU!H11 -> Nombre del producto 48 | D54: =Presupuesto!D50 -> 5000 | F54: =D54*$F$5 -> 1250 | G54: =F54*$G$5 -> 262.5 | H54: =D54*$H$5 -> 125 | I54: =$I$5 -> 800 | J54: =F54+G54+H54+I54 -> 2437.5 | L54: =D54-J54 -> 2562.5 | M54: =L54/D54 -> 0.5125 | O54: =(D54+$I$5)/(1-(F54+G54+H54)/D54) -> 8624.5353
B55: 49 | C55: =MENU!H12 -> Nombre del producto 49 | D55: =Presupuesto!D51 -> 5000 | F55: =D55*$F$5 -> 1250 | G55: =F55*$G$5 -> 262.5 | H55: =D55*$H$5 -> 125 | I55: =$I$5 -> 800 | J55: =F55+G55+H55+I55 -> 2437.5 | L55: =D55-J55 -> 2562.5 | M55: =L55/D55 -> 0.5125 | O55: =(D55+$I$5)/(1-(F55+G55+H55)/D55) -> 8624.5353
B56: 50 | C56: =MENU!H13 -> Nombre del producto 50 | D56: =Presupuesto!D52 -> 5000 | F56: =D56*$F$5 -> 1250 | G56: =F56*$G$5 -> 262.5 | H56: =D56*$H$5 -> 125 | I56: =$I$5 -> 800 | J56: =F56+G56+H56+I56 -> 2437.5 | L56: =D56-J56 -> 2562.5 | M56: =L56/D56 -> 0.5125 | O56: =(D56+$I$5)/(1-(F56+G56+H56)/D56) -> 8624.5353
...

Sheet 1
B2: =MENU!B4 -> Nombre del producto 1
B4: COSTO DE LOS INGREDIENTES
B5: Ingrediente | C5: Cantidad | D5: U. medida | E5: Precio unitario | F5: Total | H5: RESUMEN FINAL | K5: 1
D6: =IFERROR(VLOOKUP(B6,Ingredientes!$B:$D,3,FALSE),0) -> 0 | E6: =IFERROR(VLOOKUP(B6,Ingredientes!$B:$C,2,FALSE),0) -> 0 | F6: =C6*E6 -> 0 | H6: Costo materiales: | I6: =F31 -> 0
D7: =IFERROR(VLOOKUP(B7,Ingredientes!$B:$D,3,FALSE),0) -> 0 | E7: =IFERROR(VLOOKUP(B7,Ingredientes!$B:$C,2,FALSE),0) -> 0 | F7: =C7*E7 -> 0 | H7: Costo laboral: | I7: =E34 -> 0
D8: =IFERROR(VLOOKUP(B8,Ingredientes!$B:$D,3,FALSE),0) -> 0 | E8: =IFERROR(VLOOKUP(B8,Ingredientes!$B:$C,2,FALSE),0) -> 0 | F8: =C8*E8 -> 0 | H8: Costo fijo: | I8: =C37
D9: =IFERROR(VLOOKUP(B9,Ingredientes!$B:$D,3,FALSE),0) -> 0 | E9: =IFERROR(VLOOKUP(B9,Ingredientes!$B:$C,2,FALSE),0) -> 0 | F9: =C9*E9 -> 0 | H9: Costo Total | I9: =IFERROR(SUM($I$6:$I$8)/K5,0) -> 0
D10: =IFERROR(VLOOKUP(B10,Ingredientes!$B:$D,3,FALSE),0) -> 0 | E10: =IFERROR(VLOOKUP(B10,Ingredientes!$B:$C,2,FALSE),0) -> 0 | F10: =C10*E10 -> 0
D11: =IFERROR(VLOOKUP(B11,Ingredientes!$B:$D,3,FALSE),0) -> 0 | E11: =IFERROR(VLOOKUP(B11,Ingredientes!$B:$C,2,FALSE),0) -> 0 | F11: =C11*E11 -> 0 | H11: Precio de venta | I11: 7000
D12: =IFERROR(VLOOKUP(B12,Ingredientes!$B:$D,3,FALSE),0) -> 0 | E12: =IFERROR(VLOOKUP(B12,Ingredientes!$B:$C,2,FALSE),0) -> 0 | F12: =C12*E12 -> 0 | H12: Utilidad en $ | I12: =I11-I9 -> 7000
D13: =IFERROR(VLOOKUP(B13,Ingredientes!$B:$D,3,FALSE),0) -> 0 | E13: =IFERROR(VLOOKUP(B13,Ingredientes!$B:$C,2,FALSE),0) -> 0 | F13: =C13*E13 -> 0 | H13: Utilidad en $ | I13: =I12/I11 -> 1
D14: =IFERROR(VLOOKUP(B14,Ingredientes!$B:$D,3,FALSE),0) -> 0 | E14: =IFERROR(VLOOKUP(B14,Ingredientes!$B:$C,2,FALSE),0) -> 0 | F14: =C14*E14 -> 0 | H14: Punto de equilibrio (u) | I14: =CIF!C67/(I11-I6-I7) -> 0
D15: =IFERROR(VLOOKUP(B15,Ingredientes!$B:$D,3,FALSE),0) -> 0 | E15: =IFERROR(VLOOKUP(B15,Ingredientes!$B:$C,2,FALSE),0) -> 0 | F15: =C15*E15 -> 0
D16: =IFERROR(VLOOKUP(B16,Ingredientes!$B:$D,3,FALSE),0) -> 0 | E16: =IFERROR(VLOOKUP(B16,Ingredientes!$B:$C,2,FALSE),0) -> 0 | F16: =C16*E16 -> 0
D17: =IFERROR(VLOOKUP(B17,Ingredientes!$B:$D,3,FALSE),0) -> 0 | E17: =IFERROR(VLOOKUP(B17,Ingredientes!$B:$C,2,FALSE),0) -> 0 | F17: =C17*E17 -> 0
D18: =IFERROR(VLOOKUP(B18,Ingredientes!$B:$D,3,FALSE),0) -> 0 | E18: =IFERROR(VLOOKUP(B18,Ingredientes!$B:$C,2,FALSE),0) -> 0 | F18: =C18*E18 -> 0
D19: =IFERROR(VLOOKUP(B19,Ingredientes!$B:$D,3,FALSE),0) -> 0 | E19: =IFERROR(VLOOKUP(B19,Ingredientes!$B:$C,2,FALSE),0) -> 0 | F19: =C19*E19 -> 0
D20: =IFERROR(VLOOKUP(B20,Ingredientes!$B:$D,3,FALSE),0) -> 0 | E20: =IFERROR(VLOOKUP(B20,Ingredientes!$B:$C,2,FALSE),0) -> 0 | F20: =C20*E20 -> 0
D21: =IFERROR(VLOOKUP(B21,Ingredientes!$B:$D,3,FALSE),0) -> 0 | E21: =IFERROR(VLOOKUP(B21,Ingredientes!$B:$C,2,FALSE),0) -> 0 | F21: =C21*E21 -> 0
D22: =IFERROR(VLOOKUP(B22,Ingredientes!$B:$D,3,FALSE),0) -> 0 | E22: =IFERROR(VLOOKUP(B22,Ingredientes!$B:$C,2,FALSE),0) -> 0 | F22: =C22*E22 -> 0
D23: =IFERROR(VLOOKUP(B23,Ingredientes!$B:$D,3,FALSE),0) -> 0 | E23: =IFERROR(VLOOKUP(B23,Ingredientes!$B:$C,2,FALSE),0) -> 0 | F23: =C23*E23 -> 0
D24: =IFERROR(VLOOKUP(B24,Ingredientes!$B:$D,3,FALSE),0) -> 0 | E24: =IFERROR(VLOOKUP(B24,Ingredientes!$B:$C,2,FALSE),0) -> 0 | F24: =C24*E24 -> 0
D25: =IFERROR(VLOOKUP(B25,Ingredientes!$B:$D,3,FALSE),0) -> 0 | E25: =IFERROR(VLOOKUP(B25,Ingredientes!$B:$C,2,FALSE),0) -> 0 | F25: =C25*E25 -> 0
D26: =IFERROR(VLOOKUP(B26,Ingredientes!$B:$D,3,FALSE),0) -> 0 | E26: =IFERROR(VLOOKUP(B26,Ingredientes!$B:$C,2,FALSE),0) -> 0 | F26: =C26*E26 -> 0
... D30: =IFERROR(VLOOKUP(B30,Ingredientes!$B:$D,3,FALSE),0) -> 0 | E30: =IFERROR(VLOOKUP(B30,Ingredientes!$B:$C,2,FALSE),0) -> 0 | F30: =C30*E30 -> 0
F31: =SUM(F6:F30) -> 0
H32: CALCULADORA DE AYUDA
B33: CONCEPTO | C33: Horas x unidad | D33: Costo por hora | E33: TOTAL | H33: MINUTOS | I33: HORAS
B34: MANO DE OBRA | C34: 0 | D34: =MO!E18 -> 0 | E34: =C34*D34 -> 0 | H34: 15 | I34: =H34/60 -> 0.25
B36: CONCEPTO | C36: Costos fijos por receta
B37: COSTOS FIJOS | C37: =VLOOKUP(B2,CIF!F:I,4,FALSE)

Sheet 2
B2: =MENU!B5 -> Nombre del producto 2
B4: COSTO DE LOS INGREDIENTES
B5: Ingrediente | C5: Cantidad | D5: U. medida | E5: Precio unitario | F5: Total | H5: RESUMEN FINAL | K5: 1
D6: =IFERROR(VLOOKUP(B6,Ingredientes!$B:$D,3,FALSE),0) -> 0 | E6: =IFERROR(VLOOKUP(B6,Ingredientes!$B:$C,2,FALSE),0) -> 0 | F6: =C6*E6 -> 0 | H6: Costo materiales: | I6: =F31 -> 0
D7: =IFERROR(VLOOKUP(B7,Ingredientes!$B:$D,3,FALSE),0) -> 0 | E7: =IFERROR(VLOOKUP(B7,Ingredientes!$B:$C,2,FALSE),0) -> 0 | F7: =C7*E7 -> 0 | H7: Costo laboral: | I7: =E34 -> 0
D8: =IFERROR(VLOOKUP(B8,Ingredientes!$B:$D,3,FALSE),0) -> 0 | E8: =IFERROR(VLOOKUP(B8,Ingredientes!$B:$C,2,FALSE),0) -> 0 | F8: =C8*E8 -> 0 | H8: Costo fijo: | I8: =C37
D9: =IFERROR(VLOOKUP(B9,Ingredientes!$B:$D,3,FALSE),0) -> 0 | E9: =IFERROR(VLOOKUP(B9,Ingredientes!$B:$C,2,FALSE),0) -> 0 | F9: =C9*E9 -> 0 | H9: Costo Total | I9: =IFERROR(SUM($I$6:$I$8)/K5,0) -> 0
D10: =IFERROR(VLOOKUP(B10,Ingredientes!$B:$D,3,FALSE),0) -> 0 | E10: =IFERROR(VLOOKUP(B10,Ingredientes!$B:$C,2,FALSE),0) -> 0 | F10: =C10*E10 -> 0
D11: =IFERROR(VLOOKUP(B11,Ingredientes!$B:$D,3,FALSE),0) -> 0 | E11: =IFERROR(VLOOKUP(B11,Ingredientes!$B:$C,2,FALSE),0) -> 0 | F11: =C11*E11 -> 0 | H11: Precio de venta | I11: 10000
D12: =IFERROR(VLOOKUP(B12,Ingredientes!$B:$D,3,FALSE),0) -> 0 | E12: =IFERROR(VLOOKUP(B12,Ingredientes!$B:$C,2,FALSE),0) -> 0 | F12: =C12*E12 -> 0 | H12: Utilidad en $ | I12: =I11-I9 -> 10000
D13: =IFERROR(VLOOKUP(B13,Ingredientes!$B:$D,3,FALSE),0) -> 0 | E13: =IFERROR(VLOOKUP(B13,Ingredientes!$B:$C,2,FALSE),0) -> 0 | F13: =C13*E13 -> 0 | H13: Utilidad en $ | I13: =I12/I11 -> 1
D14: =IFERROR(VLOOKUP(B14,Ingredientes!$B:$D,3,FALSE),0) -> 0 | E14: =IFERROR(VLOOKUP(B14,Ingredientes!$B:$C,2,FALSE),0) -> 0 | F14: =C14*E14 -> 0 | H14: Punto de equilibrio (u) | I14: =CIF!C67/(I11-I6-I7) -> 0
D15: =IFERROR(VLOOKUP(B15,Ingredientes!$B:$D,3,FALSE),0) -> 0 | E15: =IFERROR(VLOOKUP(B15,Ingredientes!$B:$C,2,FALSE),0) -> 0 | F15: =C15*E15 -> 0
D16: =IFERROR(VLOOKUP(B16,Ingredientes!$B:$D,3,FALSE),0) -> 0 | E16: =IFERROR(VLOOKUP(B16,Ingredientes!$B:$C,2,FALSE),0) -> 0 | F16: =C16*E16 -> 0
D17: =IFERROR(VLOOKUP(B17,Ingredientes!$B:$D,3,FALSE),0) -> 0 | E17: =IFERROR(VLOOKUP(B17,Ingredientes!$B:$C,2,FALSE),0) -> 0 | F17: =C17*E17 -> 0
D18: =IFERROR(VLOOKUP(B18,Ingredientes!$B:$D,3,FALSE),0) -> 0 | E18: =IFERROR(VLOOKUP(B18,Ingredientes!$B:$C,2,FALSE),0) -> 0 | F18: =C18*E18 -> 0
D19: =IFERROR(VLOOKUP(B19,Ingredientes!$B:$D,3,FALSE),0) -> 0 | E19: =IFERROR(VLOOKUP(B19,Ingredientes!$B:$C,2,FALSE),0) -> 0 | F19: =C19*E19 -> 0
D20: =IFERROR(VLOOKUP(B20,Ingredientes!$B:$D,3,FALSE),0) -> 0 | E20: =IFERROR(VLOOKUP(B20,Ingredientes!$B:$C,2,FALSE),0) -> 0 | F20: =C20*E20 -> 0
D21: =IFERROR(VLOOKUP(B21,Ingredientes!$B:$D,3,FALSE),0) -> 0 | E21: =IFERROR(VLOOKUP(B21,Ingredientes!$B:$C,2,FALSE),0) -> 0 | F21: =C21*E21 -> 0
D22: =IFERROR(VLOOKUP(B22,Ingredientes!$B:$D,3,FALSE),0) -> 0 | E22: =IFERROR(VLOOKUP(B22,Ingredientes!$B:$C,2,FALSE),0) -> 0 | F22: =C22*E22 -> 0
D23: =IFERROR(VLOOKUP(B23,Ingredientes!$B:$D,3,FALSE),0) -> 0 | E23: =IFERROR(VLOOKUP(B23,Ingredientes!$B:$C,2,FALSE),0) -> 0 | F23: =C23*E23 -> 0
D24: =IFERROR(VLOOKUP(B24,Ingredientes!$B:$D,3,FALSE),0) -> 0 | E24: =IFERROR(VLOOKUP(B24,Ingredientes!$B:$C,2,FALSE),0) -> 0 | F24: =C24*E24 -> 0
D25: =IFERROR(VLOOKUP(B25,Ingredientes!$B:$D,3,FALSE),0) -> 0 | E25: =IFERROR(VLOOKUP(B25,Ingredientes!$B:$C,2,FALSE),0) -> 0 | F25: =C25*E25 -> 0
D26: =IFERROR(VLOOKUP(B26,Ingredientes!$B:$D,3,FALSE),0) -> 0 | E26: =IFERROR(VLOOKUP(B26,Ingredientes!$B:$C,2,FALSE),0) -> 0 | F26: =C26*E26 -> 0
... D30: =IFERROR(VLOOKUP(B30,Ingredientes!$B:$D,3,FALSE),0) -> 0 | E30: =IFERROR(VLOOKUP(B30,Ingredientes!$B:$C,2,FALSE),0) -> 0 | F30: =C30*E30 -> 0
F31: =SUM(F6:F30) -> 0
H32: CALCULADORA DE AYUDA
B33: CONCEPTO | C33: Horas x unidad | D33: Costo por hora | E33: TOTAL | H33: MINUTOS | I33: HORAS
B34: MANO DE OBRA | C34: 0 | D34: =MO!E18 -> 0 | E34: =C34*D34 -> 0 | H34: 20 | I34: =H34/60 -> 0.33333333
B36: CONCEPTO | C36: Costos fijos por receta
B37: COSTOS FIJOS | C37: =VLOOKUP(B2,CIF!F:I,4,FALSE)

Sheet 3
B2: =MENU!B6 -> Nombre del producto 3
B4: COSTO DE LOS INGREDIENTES
B5: Ingrediente | C5: Cantidad | D5: U. medida | E5: Precio unitario | F5: Total | H5: RESUMEN FINAL | K5: 1
D6: =IFERROR(VLOOKUP(B6,Ingredientes!$B:$D,3,FALSE),0) -> 0 | E6: =IFERROR(VLOOKUP(B6,Ingredientes!$B:$C,2,FALSE),0) -> 0 | F6: =C6*E6 -> 0 | H6: Costo materiales: | I6: =F31 -> 0
D7: =IFERROR(VLOOKUP(B7,Ingredientes!$B:$D,3,FALSE),0) -> 0 | E7: =IFERROR(VLOOKUP(B7,Ingredientes!$B:$C,2,FALSE),0) -> 0 | F7: =C7*E7 -> 0 | H7: Costo laboral: | I7: =E34 -> 0
D8: =IFERROR(VLOOKUP(B8,Ingredientes!$B:$D,3,FALSE),0) -> 0 | E8: =IFERROR(VLOOKUP(B8,Ingredientes!$B:$C,2,FALSE),0) -> 0 | F8: =C8*E8 -> 0 | H8: Costo fijo: | I8: =C37
D9: =IFERROR(VLOOKUP(B9,Ingredientes!$B:$D,3,FALSE),0) -> 0 | E9: =IFERROR(VLOOKUP(B9,Ingredientes!$B:$C,2,FALSE),0) -> 0 | F9: =C9*E9 -> 0 | H9: Costo Total | I9: =IFERROR(SUM($I$6:$I$8)/K5,0) -> 0
D10: =IFERROR(VLOOKUP(B10,Ingredientes!$B:$D,3,FALSE),0) -> 0 | E10: =IFERROR(VLOOKUP(B10,Ingredientes!$B:$C,2,FALSE),0) -> 0 | F10: =C10*E10 -> 0
D11: =IFERROR(VLOOKUP(B11,Ingredientes!$B:$D,3,FALSE),0) -> 0 | E11: =IFERROR(VLOOKUP(B11,Ingredientes!$B:$C,2,FALSE),0) -> 0 | F11: =C11*E11 -> 0 | H11: Precio de venta | I11: 5000
D12: =IFERROR(VLOOKUP(B12,Ingredientes!$B:$D,3,FALSE),0) -> 0 | E12: =IFERROR(VLOOKUP(B12,Ingredientes!$B:$C,2,FALSE),0) -> 0 | F12: =C12*E12 -> 0 | H12: Utilidad en $ | I12: =I11-I9 -> 5000
D13: =IFERROR(VLOOKUP(B13,Ingredientes!$B:$D,3,FALSE),0) -> 0 | E13: =IFERROR(VLOOKUP(B13,Ingredientes!$B:$C,2,FALSE),0) -> 0 | F13: =C13*E13 -> 0 | H13: Utilidad en $ | I13: =I12/I11 -> 1
D14: =IFERROR(VLOOKUP(B14,Ingredientes!$B:$D,3,FALSE),0) -> 0 | E14: =IFERROR(VLOOKUP(B14,Ingredientes!$B:$C,2,FALSE),0) -> 0 | F14: =C14*E14 -> 0 | H14: Punto de equilibrio (u) | I14: =CIF!C67/(I11-I6-I7) -> 0
D15: =IFERROR(VLOOKUP(B15,Ingredientes!$B:$D,3,FALSE),0) -> 0 | E15: =IFERROR(VLOOKUP(B15,Ingredientes!$B:$C,2,FALSE),0) -> 0 | F15: =C15*E15 -> 0
D16: =IFERROR(VLOOKUP(B16,Ingredientes!$B:$D,3,FALSE),0) -> 0 | E16: =IFERROR(VLOOKUP(B16,Ingredientes!$B:$C,2,FALSE),0) -> 0 | F16: =C16*E16 -> 0
D17: =IFERROR(VLOOKUP(B17,Ingredientes!$B:$D,3,FALSE),0) -> 0 | E17: =IFERROR(VLOOKUP(B17,Ingredientes!$B:$C,2,FALSE),0) -> 0 | F17: =C17*E17 -> 0
D18: =IFERROR(VLOOKUP(B18,Ingredientes!$B:$D,3,FALSE),0) -> 0 | E18: =IFERROR(VLOOKUP(B18,Ingredientes!$B:$C,2,FALSE),0) -> 0 | F18: =C18*E18 -> 0
D19: =IFERROR(VLOOKUP(B19,Ingredientes!$B:$D,3,FALSE),0) -> 0 | E19: =IFERROR(VLOOKUP(B19,Ingredientes!$B:$C,2,FALSE),0) -> 0 | F19: =C19*E19 -> 0
D20: =IFERROR(VLOOKUP(B20,Ingredientes!$B:$D,3,FALSE),0) -> 0 | E20: =IFERROR(VLOOKUP(B20,Ingredientes!$B:$C,2,FALSE),0) -> 0 | F20: =C20*E20 -> 0
D21: =IFERROR(VLOOKUP(B21,Ingredientes!$B:$D,3,FALSE),0) -> 0 | E21: =IFERROR(VLOOKUP(B21,Ingredientes!$B:$C,2,FALSE),0) -> 0 | F21: =C21*E21 -> 0
D22: =IFERROR(VLOOKUP(B22,Ingredientes!$B:$D,3,FALSE),0) -> 0 | E22: =IFERROR(VLOOKUP(B22,Ingredientes!$B:$C,2,FALSE),0) -> 0 | F22: =C22*E22 -> 0
D23: =IFERROR(VLOOKUP(B23,Ingredientes!$B:$D,3,FALSE),0) -> 0 | E23: =IFERROR(VLOOKUP(B23,Ingredientes!$B:$C,2,FALSE),0) -> 0 | F23: =C23*E23 -> 0
D24: =IFERROR(VLOOKUP(B24,Ingredientes!$B:$D,3,FALSE),0) -> 0 | E24: =IFERROR(VLOOKUP(B24,Ingredientes!$B:$C,2,FALSE),0) -> 0 | F24: =C24*E24 -> 0
D25: =IFERROR(VLOOKUP(B25,Ingredientes!$B:$D,3,FALSE),0) -> 0 | E25: =IFERROR(VLOOKUP(B25,Ingredientes!$B:$C,2,FALSE),0) -> 0 | F25: =C25*E25 -> 0
D26: =IFERROR(VLOOKUP(B26,Ingredientes!$B:$D,3,FALSE),0) -> 0 | E26: =IFERROR(VLOOKUP(B26,Ingredientes!$B:$C,2,FALSE),0) -> 0 | F26: =C26*E26 -> 0
... D30: =IFERROR(VLOOKUP(B30,Ingredientes!$B:$D,3,FALSE),0) -> 0 | E30: =IFERROR(VLOOKUP(B30,Ingredientes!$B:$C,2,FALSE),0) -> 0 | F30: =C30*E30 -> 0
F31: =SUM(F6:F30) -> 0
H32: CALCULADORA DE AYUDA
B33: CONCEPTO | C33: Horas x unidad | D33: Costo por hora | E33: TOTAL | H33: MINUTOS | I33: HORAS
B34: MANO DE OBRA | D34: =MO!E18 -> 0 | E34: =C34*D34 -> 0 | I34: =H34/60 -> 0
B36: CONCEPTO | C36: Costos fijos por receta
B37: COSTOS FIJOS | C37: =VLOOKUP(B2,CIF!F:I,4,FALSE)

Sheet 4
B2: =MENU!B7 -> Nombre del producto 4
B4: COSTO DE LOS INGREDIENTES
B5: Ingrediente | C5: Cantidad | D5: U. medida | E5: Precio unitario | F5: Total | H5: RESUMEN FINAL | K5: 1
D6: =IFERROR(VLOOKUP(B6,Ingredientes!$B:$D,3,FALSE),0) -> 0 | E6: =IFERROR(VLOOKUP(B6,Ingredientes!$B:$C,2,FALSE),0) -> 0 | F6: =C6*E6 -> 0 | H6: Costo materiales: | I6: =F31 -> 0
D7: =IFERROR(VLOOKUP(B7,Ingredientes!$B:$D,3,FALSE),0) -> 0 | E7: =IFERROR(VLOOKUP(B7,Ingredientes!$B:$C,2,FALSE),0) -> 0 | F7: =C7*E7 -> 0 | H7: Costo laboral: | I7: =E34 -> 0
D8: =IFERROR(VLOOKUP(B8,Ingredientes!$B:$D,3,FALSE),0) -> 0 | E8: =IFERROR(VLOOKUP(B8,Ingredientes!$B:$C,2,FALSE),0) -> 0 | F8: =C8*E8 -> 0 | H8: Costo fijo: | I8: =C37
D9: =IFERROR(VLOOKUP(B9,Ingredientes!$B:$D,3,FALSE),0) -> 0 | E9: =IFERROR(VLOOKUP(B9,Ingredientes!$B:$C,2,FALSE),0) -> 0 | F9: =C9*E9 -> 0 | H9: Costo Total | I9: =IFERROR(SUM($I$6:$I$8)/K5,0) -> 0
D10: =IFERROR(VLOOKUP(B10,Ingredientes!$B:$D,3,FALSE),0) -> 0 | E10: =IFERROR(VLOOKUP(B10,Ingredientes!$B:$C,2,FALSE),0) -> 0 | F10: =C10*E10 -> 0
D11: =IFERROR(VLOOKUP(B11,Ingredientes!$B:$D,3,FALSE),0) -> 0 | E11: =IFERROR(VLOOKUP(B11,Ingredientes!$B:$C,2,FALSE),0) -> 0 | F11: =C11*E11 -> 0 | H11: Precio de venta | I11: 5000
D12: =IFERROR(VLOOKUP(B12,Ingredientes!$B:$D,3,FALSE),0) -> 0 | E12: =IFERROR(VLOOKUP(B12,Ingredientes!$B:$C,2,FALSE),0) -> 0 | F12: =C12*E12 -> 0 | H12: Utilidad en $ | I12: =I11-I9 -> 5000
D13: =IFERROR(VLOOKUP(B13,Ingredientes!$B:$D,3,FALSE),0) -> 0 | E13: =IFERROR(VLOOKUP(B13,Ingredientes!$B:$C,2,FALSE),0) -> 0 | F13: =C13*E13 -> 0 | H13: Utilidad en $ | I13: =I12/I11 -> 1
D14: =IFERROR(VLOOKUP(B14,Ingredientes!$B:$D,3,FALSE),0) -> 0 | E14: =IFERROR(VLOOKUP(B14,Ingredientes!$B:$C,2,FALSE),0) -> 0 | F14: =C14*E14 -> 0 | H14: Punto de equilibrio (u) | I14: =CIF!C67/(I11-I6-I7) -> 0
D15: =IFERROR(VLOOKUP(B15,Ingredientes!$B:$D,3,FALSE),0) -> 0 | E15: =IFERROR(VLOOKUP(B15,Ingredientes!$B:$C,2,FALSE),0) -> 0 | F15: =C15*E15 -> 0
D16: =IFERROR(VLOOKUP(B16,Ingredientes!$B:$D,3,FALSE),0) -> 0 | E16: =IFERROR(VLOOKUP(B16,Ingredientes!$B:$C,2,FALSE),0) -> 0 | F16: =C16*E16 -> 0
D17: =IFERROR(VLOOKUP(B17,Ingredientes!$B:$D,3,FALSE),0) -> 0 | E17: =IFERROR(VLOOKUP(B17,Ingredientes!$B:$C,2,FALSE),0) -> 0 | F17: =C17*E17 -> 0
D18: =IFERROR(VLOOKUP(B18,Ingredientes!$B:$D,3,FALSE),0) -> 0 | E18: =IFERROR(VLOOKUP(B18,Ingredientes!$B:$C,2,FALSE),0) -> 0 | F18: =C18*E18 -> 0
D19: =IFERROR(VLOOKUP(B19,Ingredientes!$B:$D,3,FALSE),0) -> 0 | E19: =IFERROR(VLOOKUP(B19,Ingredientes!$B:$C,2,FALSE),0) -> 0 | F19: =C19*E19 -> 0
D20: =IFERROR(VLOOKUP(B20,Ingredientes!$B:$D,3,FALSE),0) -> 0 | E20: =IFERROR(VLOOKUP(B20,Ingredientes!$B:$C,2,FALSE),0) -> 0 | F20: =C20*E20 -> 0
D21: =IFERROR(VLOOKUP(B21,Ingredientes!$B:$D,3,FALSE),0) -> 0 | E21: =IFERROR(VLOOKUP(B21,Ingredientes!$B:$C,2,FALSE),0) -> 0 | F21: =C21*E21 -> 0
D22: =IFERROR(VLOOKUP(B22,Ingredientes!$B:$D,3,FALSE),0) -> 0 | E22: =IFERROR(VLOOKUP(B22,Ingredientes!$B:$C,2,FALSE),0) -> 0 | F22: =C22*E22 -> 0
D23: =IFERROR(VLOOKUP(B23,Ingredientes!$B:$D,3,FALSE),0) -> 0 | E23: =IFERROR(VLOOKUP(B23,Ingredientes!$B:$C,2,FALSE),0) -> 0 | F23: =C23*E23 -> 0
D24: =IFERROR(VLOOKUP(B24,Ingredientes!$B:$D,3,FALSE),0) -> 0 | E24: =IFERROR(VLOOKUP(B24,Ingredientes!$B:$C,2,FALSE),0) -> 0 | F24: =C24*E24 -> 0
D25: =IFERROR(VLOOKUP(B25,Ingredientes!$B:$D,3,FALSE),0) -> 0 | E25: =IFERROR(VLOOKUP(B25,Ingredientes!$B:$C,2,FALSE),0) -> 0 | F25: =C25*E25 -> 0
D26: =IFERROR(VLOOKUP(B26,Ingredientes!$B:$D,3,FALSE),0) -> 0 | E26: =IFERROR(VLOOKUP(B26,Ingredientes!$B:$C,2,FALSE),0) -> 0 | F26: =C26*E26 -> 0
... D30: =IFERROR(VLOOKUP(B30,Ingredientes!$B:$D,3,FALSE),0) -> 0 | E30: =IFERROR(VLOOKUP(B30,Ingredientes!$B:$C,2,FALSE),0) -> 0 | F30: =C30*E30 -> 0
F31: =SUM(F6:F30) -> 0
H32: CALCULADORA DE AYUDA
B33: CONCEPTO | C33: Horas x unidad | D33: Costo por hora | E33: TOTAL | H33: MINUTOS | I33: HORAS
B34: MANO DE OBRA | D34: =MO!E18 -> 0 | E34: =C34*D34 -> 0 | I34: =H34/60 -> 0
B36: CONCEPTO | C36: Costos fijos por receta
B37: COSTOS FIJOS | C37: =VLOOKUP(B2,CIF!F:I,4,FALSE)

Sheet 5
B2: =MENU!B8 -> Nombre del producto 5
B4: COSTO DE LOS INGREDIENTES
B5: Ingrediente | C5: Cantidad | D5: U. medida | E5: Precio unitario | F5: Total | H5: RESUMEN FINAL | K5: 1
D6: =IFERROR(VLOOKUP(B6,Ingredientes!$B:$D,3,FALSE),0) -> 0 | E6: =IFERROR(VLOOKUP(B6,Ingredientes!$B:$C,2,FALSE),0) -> 0 | F6: =C6*E6 -> 0 | H6: Costo materiales: | I6: =F31 -> 0
D7: =IFERROR(VLOOKUP(B7,Ingredientes!$B:$D,3,FALSE),0) -> 0 | E7: =IFERROR(VLOOKUP(B7,Ingredientes!$B:$C,2,FALSE),0) -> 0 | F7: =C7*E7 -> 0 | H7: Costo laboral: | I7: =E34 -> 0
D8: =IFERROR(VLOOKUP(B8,Ingredientes!$B:$D,3,FALSE),0) -> 0 | E8: =IFERROR(VLOOKUP(B8,Ingredientes!$B:$C,2,FALSE),0) -> 0 | F8: =C8*E8 -> 0 | H8: Costo fijo: | I8: =C37
D9: =IFERROR(VLOOKUP(B9,Ingredientes!$B:$D,3,FALSE),0) -> 0 | E9: =IFERROR(VLOOKUP(B9,Ingredientes!$B:$C,2,FALSE),0) -> 0 | F9: =C9*E9 -> 0 | H9: Costo Total | I9: =IFERROR(SUM($I$6:$I$8)/K5,0) -> 0
D10: =IFERROR(VLOOKUP(B10,Ingredientes!$B:$D,3,FALSE),0) -> 0 | E10: =IFERROR(VLOOKUP(B10,Ingredientes!$B:$C,2,FALSE),0) -> 0 | F10: =C10*E10 -> 0
D11: =IFERROR(VLOOKUP(B11,Ingredientes!$B:$D,3,FALSE),0) -> 0 | E11: =IFERROR(VLOOKUP(B11,Ingredientes!$B:$C,2,FALSE),0) -> 0 | F11: =C11*E11 -> 0 | H11: Precio de venta | I11: 5000
D12: =IFERROR(VLOOKUP(B12,Ingredientes!$B:$D,3,FALSE),0) -> 0 | E12: =IFERROR(VLOOKUP(B12,Ingredientes!$B:$C,2,FALSE),0) -> 0 | F12: =C12*E12 -> 0 | H12: Utilidad en $ | I12: =I11-I9 -> 5000
D13: =IFERROR(VLOOKUP(B13,Ingredientes!$B:$D,3,FALSE),0) -> 0 | E13: =IFERROR(VLOOKUP(B13,Ingredientes!$B:$C,2,FALSE),0) -> 0 | F13: =C13*E13 -> 0 | H13: Utilidad en $ | I13: =I12/I11 -> 1
D14: =IFERROR(VLOOKUP(B14,Ingredientes!$B:$D,3,FALSE),0) -> 0 | E14: =IFERROR(VLOOKUP(B14,Ingredientes!$B:$C,2,FALSE),0) -> 0 | F14: =C14*E14 -> 0 | H14: Punto de equilibrio (u) | I14: =CIF!C67/(I11-I6-I7) -> 0
D15: =IFERROR(VLOOKUP(B15,Ingredientes!$B:$D,3,FALSE),0) -> 0 | E15: =IFERROR(VLOOKUP(B15,Ingredientes!$B:$C,2,FALSE),0) -> 0 | F15: =C15*E15 -> 0
D16: =IFERROR(VLOOKUP(B16,Ingredientes!$B:$D,3,FALSE),0) -> 0 | E16: =IFERROR(VLOOKUP(B16,Ingredientes!$B:$C,2,FALSE),0) -> 0 | F16: =C16*E16 -> 0
D17: =IFERROR(VLOOKUP(B17,Ingredientes!$B:$D,3,FALSE),0) -> 0 | E17: =IFERROR(VLOOKUP(B17,Ingredientes!$B:$C,2,FALSE),0) -> 0 | F17: =C17*E17 -> 0
D18: =IFERROR(VLOOKUP(B18,Ingredientes!$B:$D,3,FALSE),0) -> 0 | E18: =IFERROR(VLOOKUP(B18,Ingredientes!$B:$C,2,FALSE),0) -> 0 | F18: =C18*E18 -> 0
D19: =IFERROR(VLOOKUP(B19,Ingredientes!$B:$D,3,FALSE),0) -> 0 | E19: =IFERROR(VLOOKUP(B19,Ingredientes!$B:$C,2,FALSE),0) -> 0 | F19: =C19*E19 -> 0
D20: =IFERROR(VLOOKUP(B20,Ingredientes!$B:$D,3,FALSE),0) -> 0 | E20: =IFERROR(VLOOKUP(B20,Ingredientes!$B:$C,2,FALSE),0) -> 0 | F20: =C20*E20 -> 0
D21: =IFERROR(VLOOKUP(B21,Ingredientes!$B:$D,3,FALSE),0) -> 0 | E21: =IFERROR(VLOOKUP(B21,Ingredientes!$B:$C,2,FALSE),0) -> 0 | F21: =C21*E21 -> 0
D22: =IFERROR(VLOOKUP(B22,Ingredientes!$B:$D,3,FALSE),0) -> 0 | E22: =IFERROR(VLOOKUP(B22,Ingredientes!$B:$C,2,FALSE),0) -> 0 | F22: =C22*E22 -> 0
D23: =IFERROR(VLOOKUP(B23,Ingredientes!$B:$D,3,FALSE),0) -> 0 | E23: =IFERROR(VLOOKUP(B23,Ingredientes!$B:$C,2,FALSE),0) -> 0 | F23: =C23*E23 -> 0
D24: =IFERROR(VLOOKUP(B24,Ingredientes!$B:$D,3,FALSE),0) -> 0 | E24: =IFERROR(VLOOKUP(B24,Ingredientes!$B:$C,2,FALSE),0) -> 0 | F24: =C24*E24 -> 0
D25: =IFERROR(VLOOKUP(B25,Ingredientes!$B:$D,3,FALSE),0) -> 0 | E25: =IFERROR(VLOOKUP(B25,Ingredientes!$B:$C,2,FALSE),0) -> 0 | F25: =C25*E25 -> 0
D26: =IFERROR(VLOOKUP(B26,Ingredientes!$B:$D,3,FALSE),0) -> 0 | E26: =IFERROR(VLOOKUP(B26,Ingredientes!$B:$C,2,FALSE),0) -> 0 | F26: =C26*E26 -> 0
... D30: =IFERROR(VLOOKUP(B30,Ingredientes!$B:$D,3,FALSE),0) -> 0 | E30: =IFERROR(VLOOKUP(B30,Ingredientes!$B:$C,2,FALSE),0) -> 0 | F30: =C30*E30 -> 0
F31: =SUM(F6:F30) -> 0
H32: CALCULADORA DE AYUDA
B33: CONCEPTO | C33: Horas x unidad | D33: Costo por hora | E33: TOTAL | H33: MINUTOS | I33: HORAS
B34: MANO DE OBRA | D34: =MO!E18 -> 0 | E34: =C34*D34 -> 0 | I34: =H34/60 -> 0
B36: CONCEPTO | C36: Costos fijos por receta
B37: COSTOS FIJOS | C37: =VLOOKUP(B2,CIF!F:I,4,FALSE)

Sheet 6
B2: =MENU!B9 -> Nombre del producto 6
B4: COSTO DE LOS INGREDIENTES
B5: Ingrediente | C5: Cantidad | D5: U. medida | E5: Precio unitario | F5: Total | H5: RESUMEN FINAL | K5: 1
D6: =IFERROR(VLOOKUP(B6,Ingredientes!$B:$D,3,FALSE),0) -> 0 | E6: =IFERROR(VLOOKUP(B6,Ingredientes!$B:$C,2,FALSE),0) -> 0 | F6: =C6*E6 -> 0 | H6: Costo materiales: | I6: =F31 -> 0
D7: =IFERROR(VLOOKUP(B7,Ingredientes!$B:$D,3,FALSE),0) -> 0 | E7: =IFERROR(VLOOKUP(B7,Ingredientes!$B:$C,2,FALSE),0) -> 0 | F7: =C7*E7 -> 0 | H7: Costo laboral: | I7: =E34 -> 0
D8: =IFERROR(VLOOKUP(B8,Ingredientes!$B:$D,3,FALSE),0) -> 0 | E8: =IFERROR(VLOOKUP(B8,Ingredientes!$B:$C,2,FALSE),0) -> 0 | F8: =C8*E8 -> 0 | H8: Costo fijo: | I8: =C37
D9: =IFERROR(VLOOKUP(B9,Ingredientes!$B:$D,3,FALSE),0) -> 0 | E9: =IFERROR(VLOOKUP(B9,Ingredientes!$B:$C,2,FALSE),0) -> 0 | F9: =C9*E9 -> 0 | H9: Costo Total | I9: =IFERROR(SUM($I$6:$I$8)/K5,0) -> 0
D10: =IFERROR(VLOOKUP(B10,Ingredientes!$B:$D,3,FALSE),0) -> 0 | E10: =IFERROR(VLOOKUP(B10,Ingredientes!$B:$C,2,FALSE),0) -> 0 | F10: =C10*E10 -> 0
D11: =IFERROR(VLOOKUP(B11,Ingredientes!$B:$D,3,FALSE),0) -> 0 | E11: =IFERROR(VLOOKUP(B11,Ingredientes!$B:$C,2,FALSE),0) -> 0 | F11: =C11*E11 -> 0 | H11: Precio de venta | I11: 5000
D12: =IFERROR(VLOOKUP(B12,Ingredientes!$B:$D,3,FALSE),0) -> 0 | E12: =IFERROR(VLOOKUP(B12,Ingredientes!$B:$C,2,FALSE),0) -> 0 | F12: =C12*E12 -> 0 | H12: Utilidad en $ | I12: =I11-I9 -> 5000
D13: =IFERROR(VLOOKUP(B13,Ingredientes!$B:$D,3,FALSE),0) -> 0 | E13: =IFERROR(VLOOKUP(B13,Ingredientes!$B:$C,2,FALSE),0) -> 0 | F13: =C13*E13 -> 0 | H13: Utilidad en $ | I13: =I12/I11 -> 1
D14: =IFERROR(VLOOKUP(B14,Ingredientes!$B:$D,3,FALSE),0) -> 0 | E14: =IFERROR(VLOOKUP(B14,Ingredientes!$B:$C,2,FALSE),0) -> 0 | F14: =C14*E14 -> 0 | H14: Punto de equilibrio (u) | I14: =CIF!C67/(I11-I6-I7) -> 0
D15: =IFERROR(VLOOKUP(B15,Ingredientes!$B:$D,3,FALSE),0) -> 0 | E15: =IFERROR(VLOOKUP(B15,Ingredientes!$B:$C,2,FALSE),0) -> 0 | F15: =C15*E15 -> 0
D16: =IFERROR(VLOOKUP(B16,Ingredientes!$B:$D,3,FALSE),0) -> 0 | E16: =IFERROR(VLOOKUP(B16,Ingredientes!$B:$C,2,FALSE),0) -> 0 | F16: =C16*E16 -> 0
D17: =IFERROR(VLOOKUP(B17,Ingredientes!$B:$D,3,FALSE),0) -> 0 | E17: =IFERROR(VLOOKUP(B17,Ingredientes!$B:$C,2,FALSE),0) -> 0 | F17: =C17*E17 -> 0
D18: =IFERROR(VLOOKUP(B18,Ingredientes!$B:$D,3,FALSE),0) -> 0 | E18: =IFERROR(VLOOKUP(B18,Ingredientes!$B:$C,2,FALSE),0) -> 0 | F18: =C18*E18 -> 0
D19: =IFERROR(VLOOKUP(B19,Ingredientes!$B:$D,3,FALSE),0) -> 0 | E19: =IFERROR(VLOOKUP(B19,Ingredientes!$B:$C,2,FALSE),0) -> 0 | F19: =C19*E19 -> 0
D20: =IFERROR(VLOOKUP(B20,Ingredientes!$B:$D,3,FALSE),0) -> 0 | E20: =IFERROR(VLOOKUP(B20,Ingredientes!$B:$C,2,FALSE),0) -> 0 | F20: =C20*E20 -> 0
D21: =IFERROR(VLOOKUP(B21,Ingredientes!$B:$D,3,FALSE),0) -> 0 | E21: =IFERROR(VLOOKUP(B21,Ingredientes!$B:$C,2,FALSE),0) -> 0 | F21: =C21*E21 -> 0
D22: =IFERROR(VLOOKUP(B22,Ingredientes!$B:$D,3,FALSE),0) -> 0 | E22: =IFERROR(VLOOKUP(B22,Ingredientes!$B:$C,2,FALSE),0) -> 0 | F22: =C22*E22 -> 0
D23: =IFERROR(VLOOKUP(B23,Ingredientes!$B:$D,3,FALSE),0) -> 0 | E23: =IFERROR(VLOOKUP(B23,Ingredientes!$B:$C,2,FALSE),0) -> 0 | F23: =C23*E23 -> 0
D24: =IFERROR(VLOOKUP(B24,Ingredientes!$B:$D,3,FALSE),0) -> 0 | E24: =IFERROR(VLOOKUP(B24,Ingredientes!$B:$C,2,FALSE),0) -> 0 | F24: =C24*E24 -> 0
D25: =IFERROR(VLOOKUP(B25,Ingredientes!$B:$D,3,FALSE),0) -> 0 | E25: =IFERROR(VLOOKUP(B25,Ingredientes!$B:$C,2,FALSE),0) -> 0 | F25: =C25*E25 -> 0
D26: =IFERROR(VLOOKUP(B26,Ingredientes!$B:$D,3,FALSE),0) -> 0 | E26: =IFERROR(VLOOKUP(B26,Ingredientes!$B:$C,2,FALSE),0) -> 0 | F26: =C26*E26 -> 0
... D30: =IFERROR(VLOOKUP(B30,Ingredientes!$B:$D,3,FALSE),0) -> 0 | E30: =IFERROR(VLOOKUP(B30,Ingredientes!$B:$C,2,FALSE),0) -> 0 | F30: =C30*E30 -> 0
F31: =SUM(F6:F30) -> 0
H32: CALCULADORA DE AYUDA
B33: CONCEPTO | C33: Horas x unidad | D33: Costo por hora | E33: TOTAL | H33: MINUTOS | I33: HORAS
B34: MANO DE OBRA | D34: =MO!E18 -> 0 | E34: =C34*D34 -> 0 | I34: =H34/60 -> 0
B36: CONCEPTO | C36: Costos fijos por receta
B37: COSTOS FIJOS | C37: =VLOOKUP(B2,CIF!F:I,4,FALSE)

Sheet 7
B2: =MENU!B10 -> Nombre del producto 7
B4: COSTO DE LOS INGREDIENTES
B5: Ingrediente | C5: Cantidad | D5: U. medida | E5: Precio unitario | F5: Total | H5: RESUMEN FINAL | K5: 1
D6: =IFERROR(VLOOKUP(B6,Ingredientes!$B:$D,3,FALSE),0) -> 0 | E6: =IFERROR(VLOOKUP(B6,Ingredientes!$B:$C,2,FALSE),0) -> 0 | F6: =C6*E6 -> 0 | H6: Costo materiales: | I6: =F31 -> 0
D7: =IFERROR(VLOOKUP(B7,Ingredientes!$B:$D,3,FALSE),0) -> 0 | E7: =IFERROR(VLOOKUP(B7,Ingredientes!$B:$C,2,FALSE),0) -> 0 | F7: =C7*E7 -> 0 | H7: Costo laboral: | I7: =E34 -> 0
D8: =IFERROR(VLOOKUP(B8,Ingredientes!$B:$D,3,FALSE),0) -> 0 | E8: =IFERROR(VLOOKUP(B8,Ingredientes!$B:$C,2,FALSE),0) -> 0 | F8: =C8*E8 -> 0 | H8: Costo fijo: | I8: =C37
D9: =IFERROR(VLOOKUP(B9,Ingredientes!$B:$D,3,FALSE),0) -> 0 | E9: =IFERROR(VLOOKUP(B9,Ingredientes!$B:$C,2,FALSE),0) -> 0 | F9: =C9*E9 -> 0 | H9: Costo Total | I9: =IFERROR(SUM($I$6:$I$8)/K5,0) -> 0
D10: =IFERROR(VLOOKUP(B10,Ingredientes!$B:$D,3,FALSE),0) -> 0 | E10: =IFERROR(VLOOKUP(B10,Ingredientes!$B:$C,2,FALSE),0) -> 0 | F10: =C10*E10 -> 0
D11: =IFERROR(VLOOKUP(B11,Ingredientes!$B:$D,3,FALSE),0) -> 0 | E11: =IFERROR(VLOOKUP(B11,Ingredientes!$B:$C,2,FALSE),0) -> 0 | F11: =C11*E11 -> 0 | H11: Precio de venta | I11: 5000
D12: =IFERROR(VLOOKUP(B12,Ingredientes!$B:$D,3,FALSE),0) -> 0 | E12: =IFERROR(VLOOKUP(B12,Ingredientes!$B:$C,2,FALSE),0) -> 0 | F12: =C12*E12 -> 0 | H12: Utilidad en $ | I12: =I11-I9 -> 5000
D13: =IFERROR(VLOOKUP(B13,Ingredientes!$B:$D,3,FALSE),0) -> 0 | E13: =IFERROR(VLOOKUP(B13,Ingredientes!$B:$C,2,FALSE),0) -> 0 | F13: =C13*E13 -> 0 | H13: Utilidad en $ | I13: =I12/I11 -> 1
D14: =IFERROR(VLOOKUP(B14,Ingredientes!$B:$D,3,FALSE),0) -> 0 | E14: =IFERROR(VLOOKUP(B14,Ingredientes!$B:$C,2,FALSE),0) -> 0 | F14: =C14*E14 -> 0 | H14: Punto de equilibrio (u) | I14: =CIF!C67/(I11-I6-I7) -> 0
D15: =IFERROR(VLOOKUP(B15,Ingredientes!$B:$D,3,FALSE),0) -> 0 | E15: =IFERROR(VLOOKUP(B15,Ingredientes!$B:$C,2,FALSE),0) -> 0 | F15: =C15*E15 -> 0
D16: =IFERROR(VLOOKUP(B16,Ingredientes!$B:$D,3,FALSE),0) -> 0 | E16: =IFERROR(VLOOKUP(B16,Ingredientes!$B:$C,2,FALSE),0) -> 0 | F16: =C16*E16 -> 0
D17: =IFERROR(VLOOKUP(B17,Ingredientes!$B:$D,3,FALSE),0) -> 0 | E17: =IFERROR(VLOOKUP(B17,Ingredientes!$B:$C,2,FALSE),0) -> 0 | F17: =C17*E17 -> 0
D18: =IFERROR(VLOOKUP(B18,Ingredientes!$B:$D,3,FALSE),0) -> 0 | E18: =IFERROR(VLOOKUP(B18,Ingredientes!$B:$C,2,FALSE),0) -> 0 | F18: =C18*E18 -> 0
D19: =IFERROR(VLOOKUP(B19,Ingredientes!$B:$D,3,FALSE),0) -> 0 | E19: =IFERROR(VLOOKUP(B19,Ingredientes!$B:$C,2,FALSE),0) -> 0 | F19: =C19*E19 -> 0
D20: =IFERROR(VLOOKUP(B20,Ingredientes!$B:$D,3,FALSE),0) -> 0 | E20: =IFERROR(VLOOKUP(B20,Ingredientes!$B:$C,2,FALSE),0) -> 0 | F20: =C20*E20 -> 0
D21: =IFERROR(VLOOKUP(B21,Ingredientes!$B:$D,3,FALSE),0) -> 0 | E21: =IFERROR(VLOOKUP(B21,Ingredientes!$B:$C,2,FALSE),0) -> 0 | F21: =C21*E21 -> 0
D22: =IFERROR(VLOOKUP(B22,Ingredientes!$B:$D,3,FALSE),0) -> 0 | E22: =IFERROR(VLOOKUP(B22,Ingredientes!$B:$C,2,FALSE),0) -> 0 | F22: =C22*E22 -> 0
D23: =IFERROR(VLOOKUP(B23,Ingredientes!$B:$D,3,FALSE),0) -> 0 | E23: =IFERROR(VLOOKUP(B23,Ingredientes!$B:$C,2,FALSE),0) -> 0 | F23: =C23*E23 -> 0
